Workbook
Name __bookmark_1: #REF!
Name __bookmark_2: #REF!

Sheet TH NV
A1: 1 | B1: 2 | C1: 3 | D1: 4 | E1: 5 | F1: 6 | G1: 7 | H1: 8 | I1: 9 | J1: 10 | K1: 11 | L1: 12 | M1: 13 | N1: 14 | O1: 15 | P1: 16 | Q1: 17 | R1: 18 | S1: 19 | T1: 20 | U1: 21 | V1: 22 | W1: 23 | X1: 24 | Y1: 25 | Z1: 26 | AA1: 27 | AB1: 28 | AC1: 29 | AD1: 30 | AE1: 31 | AF1: 32 | AG1: 33 | AH1: 34 | AI1: 35 | AJ1: 36 | AK1: 37 | AL1: 38 | AM1: 39 | AN1: 40 | AO1: 41 | AP1: 42 | AQ1: 43 | AR1: 44 | AS1: 45 | AT1: 46 | AU1: 47 | AV1: 48 | AW1: 49 | AX1: 50 | AY1: 51 | AZ1: 52 | BA1: 53 | BB1: 54 | BC1: 55 | BD1: 56 | BE1: 57 | BF1: 58 | BG1: 59
A2: Nhân Viên | D2: Dịch vụ cố định | T2: Dịch vụ di động | AJ2: CHỈ TIÊU CƯỚC - CSKH | AV2: CHƯƠNG TRÌNH TRỌNG ĐIỂM
B3: Nhân viên | D3: TB FTTH phát triển mới | H3: Supernet PTM | L3: Camera Đấu nối và bán đứt mua icloud | P3: THS Đôi dây PTM | T3: Thuê Bao trả sau | X3: Thuê bao thực 4G | AB3: Thuê bao 5G | AF3: Thuê bao standard | AJ3: Rời mạng THS | AN3: Rời mạng FTTH | AR3: Cước N1- N3 | AV3: Khôi phục THS | AZ3: Thuê Bao mybox | BD3: MYKID
D4: KH | E4: TH | F4: % | G4: Thiếu | H4: KH | I4: TH | J4: % | K4: Thiếu | L4: KH | M4: TH | N4: % | O4: Thiếu | P4: KH | Q4: TH | R4: % | S4: Thiếu | T4: KH | U4: TH | V4: % | W4: Thiếu | X4: KH | Y4: TH | Z4: % | AA4: Thiếu | AB4: KH | AC4: TH | AD4: % | AE4: Thiếu | AF4: KH | AG4: TH | AH4: % | AI4: Thiếu | AJ4: KH | AK4: TH | AL4: % | AM4: còn được | AN4: KH | AO4: TH | AP4: % | AQ4: còn được | AR4: KH | AS4: TH | AT4: ĐẠT | AU4: thiếu | AV4: KH | AW4: TH | AX4: % | AY4: Thiếu | AZ4: KH | BA4: TH | BB4: % | BC4: Thiếu | BD4: KH | BE4: TH | BF4: % | BG4: Thiếu
A5: Lê Trọng An | B5: ANLT_LDG_CNKD | C5: CNKD_LDG_ANLT | D5: =VLOOKUP(C5,'Giao CT'!$D$6:$S$20,3,0) -> 8 | E5: =VLOOKUP(C5,GBOC!$E$7:$DG$29,$B$20,0) -> 8 | F5: =IFERROR(E5/D5,0) -> 1 | G5: =D5-E5 -> 0 | H5: =VLOOKUP(C5,'Giao CT'!$D$6:$S$20,4,0) -> 4 | I5: =VLOOKUP(C5,GBOC!$E$7:$DG$29,$B$21,0) -> 6 | J5: =IFERROR(I5/H5,0) -> 1.5 | K5: =H5-I5 -> -2 | L5: =VLOOKUP(C5,'Giao CT'!$D$6:$S$20,5,0) -> 5 | M5: =VLOOKUP(C5,GBOC!$E$7:$DG$29,$B$22,0) -> 5 | N5: =IFERROR(M5/L5,0) -> 1 | O5: =L5-M5 -> 0 | P5: =VLOOKUP(C5,'Giao CT'!$D$6:$S$20,6,0) -> 5 | Q5: =VLOOKUP(C5,GBOC!$E$7:$DG$29,$B$23,0) -> 6 | R5: =IFERROR(Q5/P5,0) -> 1.2 | S5: =P5-Q5 -> -1 | T5: =VLOOKUP(C5,'Giao CT'!$D$6:$S$20,7,0) -> 4 | U5: =VLOOKUP(C5,GBOC!$E$7:$DG$29,$B$24,0) -> 4 | V5: =IFERROR(U5/T5,0) -> 1 | W5: =T5-U5 -> 0 | X5: =VLOOKUP(C5,'Giao CT'!$D$6:$S$20,8,0) -> 1 | Y5: =VLOOKUP(C5,GBOC!$E$7:$DG$29,$B$25,0) -> 1 | Z5: =IFERROR(Y5/X5,0) -> 1 | AA5: =X5-Y5 -> 0 | AB5: =VLOOKUP(C5,'Giao CT'!$D$6:$S$20,9,0) -> 30 | AC5: =VLOOKUP(C5,GBOC!$E$7:$DG$29,$B$26,0) -> 33 | AD5: =IFERROR(AC5/AB5,0) -> 1.1 | AE5: =AB5-AC5 -> -3 | AF5: =VLOOKUP(C5,'Giao CT'!$D$6:$S$20,10,0) -> 9 | AG5: =VLOOKUP(C5,GBOC!$E$7:$DG$29,$B$27,0) -> 12 | AH5: =IFERROR(AG5/AF5,0) -> 1.3333333 | AI5: =AF5-AG5 -> -3 | AJ5: =VLOOKUP(C5,'Giao CT'!$D$6:$S$20,11,0) -> 4 | AK5: 2 | AL5: =200%-IFERROR(AK5/AJ5,0) -> 1.5 | AM5: =MAX(AL5,0) -> 1.5 | AN5: =VLOOKUP(C5,'Giao CT'!$D$6:$S$20,12,0) -> 5 | AO5: =VLOOKUP(C5,GBOC!$E$7:$DG$29,$B$29,0) -> 3 | AP5: =200%-IFERROR(AO5/AN5,0) -> 1.4 | AQ5: =MAX(AP5,0) -> 1.4 | AR5: 0.97 | AS5: =(VLOOKUP(B5,cuoc!$B$7:$P$27,14,0))*1% -> 0.9641 | AT5: =IF(AS5<94.5%,0,IF(AS5<95.54%,50%,IF(AS5<AR5,80%,100%+(30%*(AS5-AR5)/3.39%)))) -> 0.8 | AU5: =AR5-AS5 -> 0.0059 | AV5: =VLOOKUP(C5,'Giao CT'!$D$6:$S$20,14,0) -> 2 | AW5: =VLOOKUP(C5,GBOC!$E$7:$DG$29,$B$31,0) -> 0 | AX5: =AW5/AV5 -> 0 | AY5: =AV5-AW5 -> 2 | AZ5: =VLOOKUP(C5,'Giao CT'!$D$6:$S$20,15,0) -> 1 | BA5: =VLOOKUP(C5,GBOC!$E$7:$DG$29,$B$32,0) -> 1 | BB5: =IFERROR(BA5/AZ5,1) -> 1 | BC5: =AZ5-BA5 -> 0 | BD5: =VLOOKUP(C5,'Giao CT'!$D$6:$S$20,16,0) -> 0 | BE5: =VLOOKUP(C5,GBOC!$E$7:$DG$29,$B$33,0) -> 0 | BF5: =IFERROR(BE5/BD5,1) -> 1 | BG5: =BD5-BE5 -> 0
A6: Bùi Thu Hằng | B6: HANGBT_LDG_CNKD | C6: CNKD_LDG_HANGBT | D6: =VLOOKUP(C6,'Giao CT'!$D$6:$S$20,3,0) -> 7 | E6: =VLOOKUP(C6,GBOC!$E$7:$DG$29,$B$20,0) -> 13 | F6: =IFERROR(E6/D6,0) -> 1.8571429 | G6: =D6-E6 -> -6 | H6: =VLOOKUP(C6,'Giao CT'!$D$6:$S$20,4,0) -> 4 | I6: =VLOOKUP(C6,GBOC!$E$7:$DG$29,$B$21,0) -> 5 | J6: =IFERROR(I6/H6,0) -> 1.25 | K6: =H6-I6 -> -1 | L6: =VLOOKUP(C6,'Giao CT'!$D$6:$S$20,5,0) -> 5 | M6: =VLOOKUP(C6,GBOC!$E$7:$DG$29,$B$22,0) -> 5 | N6: =IFERROR(M6/L6,0) -> 1 | O6: =L6-M6 -> 0 | P6: =VLOOKUP(C6,'Giao CT'!$D$6:$S$20,6,0) -> 4 | Q6: =VLOOKUP(C6,GBOC!$E$7:$DG$29,$B$23,0) -> 7 | R6: =IFERROR(Q6/P6,0) -> 1.75 | S6: =P6-Q6 -> -3 | T6: =VLOOKUP(C6,'Giao CT'!$D$6:$S$20,7,0) -> 4 | U6: =VLOOKUP(C6,GBOC!$E$7:$DG$29,$B$24,0) -> 4 | V6: =IFERROR(U6/T6,0) -> 1 | W6: =T6-U6 -> 0 | X6: =VLOOKUP(C6,'Giao CT'!$D$6:$S$20,8,0) -> 1 | Y6: =VLOOKUP(C6,GBOC!$E$7:$DG$29,$B$25,0) -> 6 | Z6: =IFERROR(Y6/X6,0) -> 6 | AA6: =X6-Y6 -> -5 | AB6: =VLOOKUP(C6,'Giao CT'!$D$6:$S$20,9,0) -> 30 | AC6: =VLOOKUP(C6,GBOC!$E$7:$DG$29,$B$26,0) -> 71 | AD6: =IFERROR(AC6/AB6,0) -> 2.3666667 | AE6: =AB6-AC6 -> -41 | AF6: =VLOOKUP(C6,'Giao CT'!$D$6:$S$20,10,0) -> 8 | AG6: =VLOOKUP(C6,GBOC!$E$7:$DG$29,$B$27,0) -> 10 | AH6: =IFERROR(AG6/AF6,0) -> 1.25 | AI6: =AF6-AG6 -> -2 | AJ6: =VLOOKUP(C6,'Giao CT'!$D$6:$S$20,11,0) -> 4 | AK6: 9 | AL6: =200%-IFERROR(AK6/AJ6,0) -> -0.25 | AM6: =MAX(AL6,0) -> 0 | AN6: =VLOOKUP(C6,'Giao CT'!$D$6:$S$20,12,0) -> 5 | AO6: =VLOOKUP(C6,GBOC!$E$7:$DG$29,$B$29,0) -> 5 | AP6: =200%-IFERROR(AO6/AN6,0) -> 1 | AQ6: =MAX(AP6,0) -> 1 | AR6: 0.97 | AS6: =(VLOOKUP(B6,cuoc!$B$7:$P$27,14,0))*1% -> 0.9605 | AT6: =IF(AS6<94.5%,0,IF(AS6<95.54%,50%,IF(AS6<AR6,80%,100%+(30%*(AS6-AR6)/3.39%)))) -> 0.8 | AU6: =AR6-AS6 -> 0.0095 | AV6: =VLOOKUP(C6,'Giao CT'!$D$6:$S$20,14,0) -> 3 | AW6: =VLOOKUP(C6,GBOC!$E$7:$DG$29,$B$31,0) -> 0 | AX6: =AW6/AV6 -> 0 | AY6: =AV6-AW6 -> 3 | AZ6: =VLOOKUP(C6,'Giao CT'!$D$6:$S$20,15,0) -> 1 | BA6: =VLOOKUP(C6,GBOC!$E$7:$DG$29,$B$32,0) -> 1 | BB6: =IFERROR(BA6/AZ6,1) -> 1 | BC6: =AZ6-BA6 -> 0 | BD6: =VLOOKUP(C6,'Giao CT'!$D$6:$S$20,16,0) -> 1 | BE6: =VLOOKUP(C6,GBOC!$E$7:$DG$29,$B$33,0) -> 0 | BF6: =IFERROR(BE6/BD6,1) -> 0 | BG6: =BD6-BE6 -> 1
A7: Bằng Trung Hiếu | B7: HIEUBT_LDG_CNKD | C7: CNKD_LDG_HIEUBT | D7: =VLOOKUP(C7,'Giao CT'!$D$6:$S$20,3,0) -> 7 | E7: =VLOOKUP(C7,GBOC!$E$7:$DG$29,$B$20,0) -> 12 | F7: =IFERROR(E7/D7,0) -> 1.7142857 | G7: =D7-E7 -> -5 | H7: =VLOOKUP(C7,'Giao CT'!$D$6:$S$20,4,0) -> 4 | I7: =VLOOKUP(C7,GBOC!$E$7:$DG$29,$B$21,0) -> 4 | J7: =IFERROR(I7/H7,0) -> 1 | K7: =H7-I7 -> 0 | L7: =VLOOKUP(C7,'Giao CT'!$D$6:$S$20,5,0) -> 5 | M7: =VLOOKUP(C7,GBOC!$E$7:$DG$29,$B$22,0) -> 5 | N7: =IFERROR(M7/L7,0) -> 1 | O7: =L7-M7 -> 0 | P7: =VLOOKUP(C7,'Giao CT'!$D$6:$S$20,6,0) -> 4 | Q7: =VLOOKUP(C7,GBOC!$E$7:$DG$29,$B$23,0) -> 4 | R7: =IFERROR(Q7/P7,0) -> 1 | S7: =P7-Q7 -> 0 | T7: =VLOOKUP(C7,'Giao CT'!$D$6:$S$20,7,0) -> 3 | U7: =VLOOKUP(C7,GBOC!$E$7:$DG$29,$B$24,0) -> 5 | V7: =IFERROR(U7/T7,0) -> 1.6666667 | W7: =T7-U7 -> -2 | X7: =VLOOKUP(C7,'Giao CT'!$D$6:$S$20,8,0) -> 1 | Y7: =VLOOKUP(C7,GBOC!$E$7:$DG$29,$B$25,0) -> 3 | Z7: =IFERROR(Y7/X7,0) -> 3 | AA7: =X7-Y7 -> -2 | AB7: =VLOOKUP(C7,'Giao CT'!$D$6:$S$20,9,0) -> 30 | AC7: =VLOOKUP(C7,GBOC!$E$7:$DG$29,$B$26,0) -> 30 | AD7: =IFERROR(AC7/AB7,0) -> 1 | AE7: =AB7-AC7 -> 0 | AF7: =VLOOKUP(C7,'Giao CT'!$D$6:$S$20,10,0) -> 8 | AG7: =VLOOKUP(C7,GBOC!$E$7:$DG$29,$B$27,0) -> 12 | AH7: =IFERROR(AG7/AF7,0) -> 1.5 | AI7: =AF7-AG7 -> -4 | AJ7: =VLOOKUP(C7,'Giao CT'!$D$6:$S$20,11,0) -> 4 | AK7: 0 | AL7: =200%-IFERROR(AK7/AJ7,0) -> 2 | AM7: =MAX(AL7,0) -> 2 | AN7: =VLOOKUP(C7,'Giao CT'!$D$6:$S$20,12,0) -> 5 | AO7: =VLOOKUP(C7,GBOC!$E$7:$DG$29,$B$29,0) -> 3 | AP7: =200%-IFERROR(AO7/AN7,0) -> 1.4 | AQ7: =MAX(AP7,0) -> 1.4 | AR7: 0.97 | AS7: =(VLOOKUP(B7,cuoc!$B$7:$P$27,14,0))*1% -> 0.9673 | AT7: =IF(AS7<94.5%,0,IF(AS7<95.54%,50%,IF(AS7<AR7,80%,100%+(30%*(AS7-AR7)/3.39%)))) -> 0.8 | AU7: =AR7-AS7 -> 0.0027 | AV7: =VLOOKUP(C7,'Giao CT'!$D$6:$S$20,14,0) -> 3 | AW7: =VLOOKUP(C7,GBOC!$E$7:$DG$29,$B$31,0) -> 1 | AX7: =AW7/AV7 -> 0.33333333 | AY7: =AV7-AW7 -> 2 | AZ7: =VLOOKUP(C7,'Giao CT'!$D$6:$S$20,15,0) -> 1 | BA7: =VLOOKUP(C7,GBOC!$E$7:$DG$29,$B$32,0) -> 1 | BB7: =IFERROR(BA7/AZ7,1) -> 1 | BC7: =AZ7-BA7 -> 0 | BD7: =VLOOKUP(C7,'Giao CT'!$D$6:$S$20,16,0) -> 0 | BE7: =VLOOKUP(C7,GBOC!$E$7:$DG$29,$B$33,0) -> 0 | BF7: =IFERROR(BE7/BD7,1) -> 1 | BG7: =BD7-BE7 -> 0
A8: Trần Văn Hùng | B8: HUNGTV1_LDG_CNKD | C8: CNKD_LDG_HUNGTV1 | D8: =VLOOKUP(C8,'Giao CT'!$D$6:$S$20,3,0) -> 7 | E8: =VLOOKUP(C8,GBOC!$E$7:$DG$29,$B$20,0) -> 5 | F8: =IFERROR(E8/D8,0) -> 0.71428571 | G8: =D8-E8 -> 2 | H8: =VLOOKUP(C8,'Giao CT'!$D$6:$S$20,4,0) -> 3 | I8: =VLOOKUP(C8,GBOC!$E$7:$DG$29,$B$21,0) -> 4 | J8: =IFERROR(I8/H8,0) -> 1.3333333 | K8: =H8-I8 -> -1 | L8: =VLOOKUP(C8,'Giao CT'!$D$6:$S$20,5,0) -> 4 | M8: =VLOOKUP(C8,GBOC!$E$7:$DG$29,$B$22,0) -> 2 | N8: =IFERROR(M8/L8,0) -> 0.5 | O8: =L8-M8 -> 2 | P8: =VLOOKUP(C8,'Giao CT'!$D$6:$S$20,6,0) -> 4 | Q8: =VLOOKUP(C8,GBOC!$E$7:$DG$29,$B$23,0) -> 3 | R8: =IFERROR(Q8/P8,0) -> 0.75 | S8: =P8-Q8 -> 1 | T8: =VLOOKUP(C8,'Giao CT'!$D$6:$S$20,7,0) -> 3 | U8: =VLOOKUP(C8,GBOC!$E$7:$DG$29,$B$24,0) -> 0 | V8: =IFERROR(U8/T8,0) -> 0 | W8: =T8-U8 -> 3 | X8: =VLOOKUP(C8,'Giao CT'!$D$6:$S$20,8,0) -> 1 | Y8: =VLOOKUP(C8,GBOC!$E$7:$DG$29,$B$25,0) -> 0 | Z8: =IFERROR(Y8/X8,0) -> 0 | AA8: =X8-Y8 -> 1 | AB8: =VLOOKUP(C8,'Giao CT'!$D$6:$S$20,9,0) -> 30 | AC8: =VLOOKUP(C8,GBOC!$E$7:$DG$29,$B$26,0) -> 9 | AD8: =IFERROR(AC8/AB8,0) -> 0.3 | AE8: =AB8-AC8 -> 21 | AF8: =VLOOKUP(C8,'Giao CT'!$D$6:$S$20,10,0) -> 8 | AG8: =VLOOKUP(C8,GBOC!$E$7:$DG$29,$B$27,0) -> 0 | AH8: =IFERROR(AG8/AF8,0) -> 0 | AI8: =AF8-AG8 -> 8 | AJ8: =VLOOKUP(C8,'Giao CT'!$D$6:$S$20,11,0) -> 4 | AK8: 5 | AL8: =200%-IFERROR(AK8/AJ8,0) -> 0.75 | AM8: =MAX(AL8,0) -> 0.75 | AN8: =VLOOKUP(C8,'Giao CT'!$D$6:$S$20,12,0) -> 3 | AO8: =VLOOKUP(C8,GBOC!$E$7:$DG$29,$B$29,0) -> 1 | AP8: =200%-IFERROR(AO8/AN8,0) -> 1.6666667 | AQ8: =MAX(AP8,0) -> 1.6666667 | AR8: 0.97 | AS8: =(VLOOKUP(B8,cuoc!$B$7:$P$27,14,0))*1% -> 0.9298 | AT8: =IF(AS8<94.5%,0,IF(AS8<95.54%,50%,IF(AS8<AR8,80%,100%+(30%*(AS8-AR8)/3.39%)))) -> 0 | AU8: =AR8-AS8 -> 0.0402 | AV8: =VLOOKUP(C8,'Giao CT'!$D$6:$S$20,14,0) -> 1 | AW8: =VLOOKUP(C8,GBOC!$E$7:$DG$29,$B$31,0) -> 0 | AX8: =AW8/AV8 -> 0 | AY8: =AV8-AW8 -> 1 | AZ8: =VLOOKUP(C8,'Giao CT'!$D$6:$S$20,15,0) -> 1 | BA8: =VLOOKUP(C8,GBOC!$E$7:$DG$29,$B$32,0) -> 0 | BB8: =IFERROR(BA8/AZ8,1) -> 0 | BC8: =AZ8-BA8 -> 1 | BD8: =VLOOKUP(C8,'Giao CT'!$D$6:$S$20,16,0) -> 0 | BE8: =VLOOKUP(C8,GBOC!$E$7:$DG$29,$B$33,0) -> 0 | BF8: =IFERROR(BE8/BD8,1) -> 1 | BG8: =BD8-BE8 -> 0
A9: Nguyễn Thị Song Hương | B9: HUONGNTS_LDG_CNKD | C9: CNKD_LDG_HUONGNTS | D9: =VLOOKUP(C9,'Giao CT'!$D$6:$S$20,3,0) -> 7 | E9: =VLOOKUP(C9,GBOC!$E$7:$DG$29,$B$20,0) -> 9 | F9: =IFERROR(E9/D9,0) -> 1.2857143 | G9: =D9-E9 -> -2 | H9: =VLOOKUP(C9,'Giao CT'!$D$6:$S$20,4,0) -> 4 | I9: =VLOOKUP(C9,GBOC!$E$7:$DG$29,$B$21,0) -> 5 | J9: =IFERROR(I9/H9,0) -> 1.25 | K9: =H9-I9 -> -1 | L9: =VLOOKUP(C9,'Giao CT'!$D$6:$S$20,5,0) -> 5 | M9: =VLOOKUP(C9,GBOC!$E$7:$DG$29,$B$22,0) -> 6 | N9: =IFERROR(M9/L9,0) -> 1.2 | O9: =L9-M9 -> -1 | P9: =VLOOKUP(C9,'Giao CT'!$D$6:$S$20,6,0) -> 4 | Q9: =VLOOKUP(C9,GBOC!$E$7:$DG$29,$B$23,0) -> 3 | R9: =IFERROR(Q9/P9,0) -> 0.75 | S9: =P9-Q9 -> 1 | T9: =VLOOKUP(C9,'Giao CT'!$D$6:$S$20,7,0) -> 4 | U9: =VLOOKUP(C9,GBOC!$E$7:$DG$29,$B$24,0) -> 3 | V9: =IFERROR(U9/T9,0) -> 0.75 | W9: =T9-U9 -> 1 | X9: =VLOOKUP(C9,'Giao CT'!$D$6:$S$20,8,0) -> 1 | Y9: =VLOOKUP(C9,GBOC!$E$7:$DG$29,$B$25,0) -> 10 | Z9: =IFERROR(Y9/X9,0) -> 10 | AA9: =X9-Y9 -> -9 | AB9: =VLOOKUP(C9,'Giao CT'!$D$6:$S$20,9,0) -> 40 | AC9: =VLOOKUP(C9,GBOC!$E$7:$DG$29,$B$26,0) -> 85 | AD9: =IFERROR(AC9/AB9,0) -> 2.125 | AE9: =AB9-AC9 -> -45 | AF9: =VLOOKUP(C9,'Giao CT'!$D$6:$S$20,10,0) -> 8 | AG9: =VLOOKUP(C9,GBOC!$E$7:$DG$29,$B$27,0) -> 7 | AH9: =IFERROR(AG9/AF9,0) -> 0.875 | AI9: =AF9-AG9 -> 1 | AJ9: =VLOOKUP(C9,'Giao CT'!$D$6:$S$20,11,0) -> 3 | AK9: 5 | AL9: =200%-IFERROR(AK9/AJ9,0) -> 0.33333333 | AM9: =MAX(AL9,0) -> 0.33333333 | AN9: =VLOOKUP(C9,'Giao CT'!$D$6:$S$20,12,0) -> 4 | AO9: =VLOOKUP(C9,GBOC!$E$7:$DG$29,$B$29,0) -> 3 | AP9: =200%-IFERROR(AO9/AN9,0) -> 1.25 | AQ9: =MAX(AP9,0) -> 1.25 | AR9: 0.97 | AS9: =(VLOOKUP(B9,cuoc!$B$7:$P$27,14,0))*1% -> 0.9465 | AT9: =IF(AS9<94.5%,0,IF(AS9<95.54%,50%,IF(AS9<AR9,80%,100%+(30%*(AS9-AR9)/3.39%)))) -> 0.5 | AU9: =AR9-AS9 -> 0.0235 | AV9: =VLOOKUP(C9,'Giao CT'!$D$6:$S$20,14,0) -> 2 | AW9: =VLOOKUP(C9,GBOC!$E$7:$DG$29,$B$31,0) -> 0 | AX9: =AW9/AV9 -> 0 | AY9: =AV9-AW9 -> 2 | AZ9: =VLOOKUP(C9,'Giao CT'!$D$6:$S$20,15,0) -> 1 | BA9: =VLOOKUP(C9,GBOC!$E$7:$DG$29,$B$32,0) -> 1 | BB9: =IFERROR(BA9/AZ9,1) -> 1 | BC9: =AZ9-BA9 -> 0 | BD9: =VLOOKUP(C9,'Giao CT'!$D$6:$S$20,16,0) -> 0 | BE9: =VLOOKUP(C9,GBOC!$E$7:$DG$29,$B$33,0) -> 0 | BF9: =IFERROR(BE9/BD9,1) -> 1 | BG9: =BD9-BE9 -> 0
A10: Vũ Thị Thu Hương | B10: HUONGVTT_LDG_CNKD | C10: CNKD_LDG_HUONGVTT | D10: =VLOOKUP(C10,'Giao CT'!$D$6:$S$20,3,0) -> 7 | E10: =VLOOKUP(C10,GBOC!$E$7:$DG$29,$B$20,0) -> 7 | F10: =IFERROR(E10/D10,0) -> 1 | G10: =D10-E10 -> 0 | H10: =VLOOKUP(C10,'Giao CT'!$D$6:$S$20,4,0) -> 3 | I10: =VLOOKUP(C10,GBOC!$E$7:$DG$29,$B$21,0) -> 3 | J10: =IFERROR(I10/H10,0) -> 1 | K10: =H10-I10 -> 0 | L10: =VLOOKUP(C10,'Giao CT'!$D$6:$S$20,5,0) -> 4 | M10: =VLOOKUP(C10,GBOC!$E$7:$DG$29,$B$22,0) -> 4 | N10: =IFERROR(M10/L10,0) -> 1 | O10: =L10-M10 -> 0 | P10: =VLOOKUP(C10,'Giao CT'!$D$6:$S$20,6,0) -> 4 | Q10: =VLOOKUP(C10,GBOC!$E$7:$DG$29,$B$23,0) -> 2 | R10: =IFERROR(Q10/P10,0) -> 0.5 | S10: =P10-Q10 -> 2 | T10: =VLOOKUP(C10,'Giao CT'!$D$6:$S$20,7,0) -> 3 | U10: =VLOOKUP(C10,GBOC!$E$7:$DG$29,$B$24,0) -> 4 | V10: =IFERROR(U10/T10,0) -> 1.3333333 | W10: =T10-U10 -> -1 | X10: =VLOOKUP(C10,'Giao CT'!$D$6:$S$20,8,0) -> 1 | Y10: =VLOOKUP(C10,GBOC!$E$7:$DG$29,$B$25,0) -> 3 | Z10: =IFERROR(Y10/X10,0) -> 3 | AA10: =X10-Y10 -> -2 | AB10: =VLOOKUP(C10,'Giao CT'!$D$6:$S$20,9,0) -> 30 | AC10: =VLOOKUP(C10,GBOC!$E$7:$DG$29,$B$26,0) -> 26 | AD10: =IFERROR(AC10/AB10,0) -> 0.86666667 | AE10: =AB10-AC10 -> 4 | AF10: =VLOOKUP(C10,'Giao CT'!$D$6:$S$20,10,0) -> 8 | AG10: =VLOOKUP(C10,GBOC!$E$7:$DG$29,$B$27,0) -> 3 | AH10: =IFERROR(AG10/AF10,0) -> 0.375 | AI10: =AF10-AG10 -> 5 | AJ10: =VLOOKUP(C10,'Giao CT'!$D$6:$S$20,11,0) -> 4 | AK10: 3 | AL10: =200%-IFERROR(AK10/AJ10,0) -> 1.25 | AM10: =MAX(AL10,0) -> 1.25 | AN10: =VLOOKUP(C10,'Giao CT'!$D$6:$S$20,12,0) -> 4 | AO10: =VLOOKUP(C10,GBOC!$E$7:$DG$29,$B$29,0) -> 1 | AP10: =200%-IFERROR(AO10/AN10,0) -> 1.75 | AQ10: =MAX(AP10,0) -> 1.75 | AR10: 0.97 | AS10: =(VLOOKUP(B10,cuoc!$B$7:$P$27,14,0))*1% -> 0.9724 | AT10: =IF(AS10<94.5%,0,IF(AS10<95.54%,50%,IF(AS10<AR10,80%,100%+(30%*(AS10-AR10)/3.39%)))) -> 1.0212389 | AU10: =AR10-AS10 -> -0.0024 | AV10: =VLOOKUP(C10,'Giao CT'!$D$6:$S$20,14,0) -> 1 | AW10: =VLOOKUP(C10,GBOC!$E$7:$DG$29,$B$31,0) -> 0 | AX10: =AW10/AV10 -> 0 | AY10: =AV10-AW10 -> 1 | AZ10: =VLOOKUP(C10,'Giao CT'!$D$6:$S$20,15,0) -> 1 | BA10: =VLOOKUP(C10,GBOC!$E$7:$DG$29,$B$32,0) -> 0 | BB10: =IFERROR(BA10/AZ10,1) -> 0 | BC10: =AZ10-BA10 -> 1 | BD10: =VLOOKUP(C10,'Giao CT'!$D$6:$S$20,16,0) -> 0 | BE10: =VLOOKUP(C10,GBOC!$E$7:$DG$29,$B$33,0) -> 0 | BF10: =IFERROR(BE10/BD10,1) -> 1 | BG10: =BD10-BE10 -> 0
A11: Phạm Mỹ Linh | B11: LINHPM_LDG_CNKD | C11: CNKD_LDG_LINHPM | D11: =VLOOKUP(C11,'Giao CT'!$D$6:$S$20,3,0) -> 8 | E11: =VLOOKUP(C11,GBOC!$E$7:$DG$29,$B$20,0) -> 8 | F11: =IFERROR(E11/D11,0) -> 1 | G11: =D11-E11 -> 0 | H11: =VLOOKUP(C11,'Giao CT'!$D$6:$S$20,4,0) -> 4 | I11: =VLOOKUP(C11,GBOC!$E$7:$DG$29,$B$21,0) -> 5 | J11: =IFERROR(I11/H11,0) -> 1.25 | K11: =H11-I11 -> -1 | L11: =VLOOKUP(C11,'Giao CT'!$D$6:$S$20,5,0) -> 5 | M11: =VLOOKUP(C11,GBOC!$E$7:$DG$29,$B$22,0) -> 4 | N11: =IFERROR(M11/L11,0) -> 0.8 | O11: =L11-M11 -> 1 | P11: =VLOOKUP(C11,'Giao CT'!$D$6:$S$20,6,0) -> 5 | Q11: =VLOOKUP(C11,GBOC!$E$7:$DG$29,$B$23,0) -> 1 | R11: =IFERROR(Q11/P11,0) -> 0.2 | S11: =P11-Q11 -> 4 | T11: =VLOOKUP(C11,'Giao CT'!$D$6:$S$20,7,0) -> 4 | U11: =VLOOKUP(C11,GBOC!$E$7:$DG$29,$B$24,0) -> 5 | V11: =IFERROR(U11/T11,0) -> 1.25 | W11: =T11-U11 -> -1 | X11: =VLOOKUP(C11,'Giao CT'!$D$6:$S$20,8,0) -> 1 | Y11: =VLOOKUP(C11,GBOC!$E$7:$DG$29,$B$25,0) -> 1 | Z11: =IFERROR(Y11/X11,0) -> 1 | AA11: =X11-Y11 -> 0 | AB11: =VLOOKUP(C11,'Giao CT'!$D$6:$S$20,9,0) -> 50 | AC11: =VLOOKUP(C11,GBOC!$E$7:$DG$29,$B$26,0) -> 71 | AD11: =IFERROR(AC11/AB11,0) -> 1.42 | AE11: =AB11-AC11 -> -21 | AF11: =VLOOKUP(C11,'Giao CT'!$D$6:$S$20,10,0) -> 9 | AG11: =VLOOKUP(C11,GBOC!$E$7:$DG$29,$B$27,0) -> 11 | AH11: =IFERROR(AG11/AF11,0) -> 1.2222222 | AI11: =AF11-AG11 -> -2 | AJ11: =VLOOKUP(C11,'Giao CT'!$D$6:$S$20,11,0) -> 4 | AK11: 19 | AL11: =200%-IFERROR(AK11/AJ11,0) -> -2.75 | AM11: =MAX(AL11,0) -> 0 | AN11: =VLOOKUP(C11,'Giao CT'!$D$6:$S$20,12,0) -> 5 | AO11: =VLOOKUP(C11,GBOC!$E$7:$DG$29,$B$29,0) -> 2 | AP11: =200%-IFERROR(AO11/AN11,0) -> 1.6 | AQ11: =MAX(AP11,0) -> 1.6 | AR11: 0.97 | AS11: =(VLOOKUP(B11,cuoc!$B$7:$P$27,14,0))*1% -> 0.959 | AT11: =IF(AS11<94.5%,0,IF(AS11<95.54%,50%,IF(AS11<AR11,80%,100%+(30%*(AS11-AR11)/3.39%)))) -> 0.8 | AU11: =AR11-AS11 -> 0.011 | AV11: =VLOOKUP(C11,'Giao CT'!$D$6:$S$20,14,0) -> 2 | AW11: =VLOOKUP(C11,GBOC!$E$7:$DG$29,$B$31,0) -> 0 | AX11: =AW11/AV11 -> 0 | AY11: =AV11-AW11 -> 2 | AZ11: =VLOOKUP(C11,'Giao CT'!$D$6:$S$20,15,0) -> 1 | BA11: =VLOOKUP(C11,GBOC!$E$7:$DG$29,$B$32,0) -> 2 | BB11: =IFERROR(BA11/AZ11,1) -> 2 | BC11: =AZ11-BA11 -> -1 | BD11: =VLOOKUP(C11,'Giao CT'!$D$6:$S$20,16,0) -> 1 | BE11: =VLOOKUP(C11,GBOC!$E$7:$DG$29,$B$33,0) -> 0 | BF11: =IFERROR(BE11/BD11,1) -> 0 | BG11: =BD11-BE11 -> 1
A12: Vũ Đức Nhuận | B12: NHUANVD_LDG_CNKD | C12: CNKD_LDG_NHUANVD | D12: =VLOOKUP(C12,'Giao CT'!$D$6:$S$20,3,0) -> 8 | E12: =VLOOKUP(C12,GBOC!$E$7:$DG$29,$B$20,0) -> 10 | F12: =IFERROR(E12/D12,0) -> 1.25 | G12: =D12-E12 -> -2 | H12: =VLOOKUP(C12,'Giao CT'!$D$6:$S$20,4,0) -> 4 | I12: =VLOOKUP(C12,GBOC!$E$7:$DG$29,$B$21,0) -> 4 | J12: =IFERROR(I12/H12,0) -> 1 | K12: =H12-I12 -> 0 | L12: =VLOOKUP(C12,'Giao CT'!$D$6:$S$20,5,0) -> 5 | M12: =VLOOKUP(C12,GBOC!$E$7:$DG$29,$B$22,0) -> 3 | N12: =IFERROR(M12/L12,0) -> 0.6 | O12: =L12-M12 -> 2 | P12: =VLOOKUP(C12,'Giao CT'!$D$6:$S$20,6,0) -> 5 | Q12: =VLOOKUP(C12,GBOC!$E$7:$DG$29,$B$23,0) -> 6 | R12: =IFERROR(Q12/P12,0) -> 1.2 | S12: =P12-Q12 -> -1 | T12: =VLOOKUP(C12,'Giao CT'!$D$6:$S$20,7,0) -> 3 | U12: =VLOOKUP(C12,GBOC!$E$7:$DG$29,$B$24,0) -> 4 | V12: =IFERROR(U12/T12,0) -> 1.3333333 | W12: =T12-U12 -> -1 | X12: =VLOOKUP(C12,'Giao CT'!$D$6:$S$20,8,0) -> 1 | Y12: =VLOOKUP(C12,GBOC!$E$7:$DG$29,$B$25,0) -> 1 | Z12: =IFERROR(Y12/X12,0) -> 1 | AA12: =X12-Y12 -> 0 | AB12: =VLOOKUP(C12,'Giao CT'!$D$6:$S$20,9,0) -> 30 | AC12: =VLOOKUP(C12,GBOC!$E$7:$DG$29,$B$26,0) -> 61 | AD12: =IFERROR(AC12/AB12,0) -> 2.0333333 | AE12: =AB12-AC12 -> -31 | AF12: =VLOOKUP(C12,'Giao CT'!$D$6:$S$20,10,0) -> 9 | AG12: =VLOOKUP(C12,GBOC!$E$7:$DG$29,$B$27,0) -> 11 | AH12: =IFERROR(AG12/AF12,0) -> 1.2222222 | AI12: =AF12-AG12 -> -2 | AJ12: =VLOOKUP(C12,'Giao CT'!$D$6:$S$20,11,0) -> 4 | AK12: 4 | AL12: =200%-IFERROR(AK12/AJ12,0) -> 1 | AM12: =MAX(AL12,0) -> 1 | AN12: =VLOOKUP(C12,'Giao CT'!$D$6:$S$20,12,0) -> 5 | AO12: =VLOOKUP(C12,GBOC!$E$7:$DG$29,$B$29,0) -> 2 | AP12: =200%-IFERROR(AO12/AN12,0) -> 1.6 | AQ12: =MAX(AP12,0) -> 1.6 | AR12: 0.97 | AS12: =(VLOOKUP(B12,cuoc!$B$7:$P$27,14,0))*1% -> 0.9592 | AT12: =IF(AS12<94.5%,0,IF(AS12<95.54%,50%,IF(AS12<AR12,80%,100%+(30%*(AS12-AR12)/3.39%)))) -> 0.8 | AU12: =AR12-AS12 -> 0.0108 | AV12: =VLOOKUP(C12,'Giao CT'!$D$6:$S$20,14,0) -> 3 | AW12: =VLOOKUP(C12,GBOC!$E$7:$DG$29,$B$31,0) -> 0 | AX12: =AW12/AV12 -> 0 | AY12: =AV12-AW12 -> 3 | AZ12: =VLOOKUP(C12,'Giao CT'!$D$6:$S$20,15,0) -> 1 | BA12: =VLOOKUP(C12,GBOC!$E$7:$DG$29,$B$32,0) -> 1 | BB12: =IFERROR(BA12/AZ12,1) -> 1 | BC12: =AZ12-BA12 -> 0 | BD12: =VLOOKUP(C12,'Giao CT'!$D$6:$S$20,16,0) -> 0 | BE12: =VLOOKUP(C12,GBOC!$E$7:$DG$29,$B$33,0) -> 0 | BF12: =IFERROR(BE12/BD12,1) -> 1 | BG12: =BD12-BE12 -> 0
A13: Nguyễn Thị Thu Phượng | B13: PHUONGNTT1_LDG_CNKD | C13: CNKD_LDG_PHUONGNTT1 | D13: =VLOOKUP(C13,'Giao CT'!$D$6:$S$20,3,0) -> 7 | E13: =VLOOKUP(C13,GBOC!$E$7:$DG$29,$B$20,0) -> 7 | F13: =IFERROR(E13/D13,0) -> 1 | G13: =D13-E13 -> 0 | H13: =VLOOKUP(C13,'Giao CT'!$D$6:$S$20,4,0) -> 4 | I13: =VLOOKUP(C13,GBOC!$E$7:$DG$29,$B$21,0) -> 10 | J13: =IFERROR(I13/H13,0) -> 2.5 | K13: =H13-I13 -> -6 | L13: =VLOOKUP(C13,'Giao CT'!$D$6:$S$20,5,0) -> 5 | M13: =VLOOKUP(C13,GBOC!$E$7:$DG$29,$B$22,0) -> 3 | N13: =IFERROR(M13/L13,0) -> 0.6 | O13: =L13-M13 -> 2 | P13: =VLOOKUP(C13,'Giao CT'!$D$6:$S$20,6,0) -> 4 | Q13: =VLOOKUP(C13,GBOC!$E$7:$DG$29,$B$23,0) -> 6 | R13: =IFERROR(Q13/P13,0) -> 1.5 | S13: =P13-Q13 -> -2 | T13: =VLOOKUP(C13,'Giao CT'!$D$6:$S$20,7,0) -> 4 | U13: =VLOOKUP(C13,GBOC!$E$7:$DG$29,$B$24,0) -> 8 | V13: =IFERROR(U13/T13,0) -> 2 | W13: =T13-U13 -> -4 | X13: =VLOOKUP(C13,'Giao CT'!$D$6:$S$20,8,0) -> 1 | Y13: =VLOOKUP(C13,GBOC!$E$7:$DG$29,$B$25,0) -> 12 | Z13: =IFERROR(Y13/X13,0) -> 12 | AA13: =X13-Y13 -> -11 | AB13: =VLOOKUP(C13,'Giao CT'!$D$6:$S$20,9,0) -> 30 | AC13: =VLOOKUP(C13,GBOC!$E$7:$DG$29,$B$26,0) -> 73 | AD13: =IFERROR(AC13/AB13,0) -> 2.4333333 | AE13: =AB13-AC13 -> -43 | AF13: =VLOOKUP(C13,'Giao CT'!$D$6:$S$20,10,0) -> 8 | AG13: =VLOOKUP(C13,GBOC!$E$7:$DG$29,$B$27,0) -> 8 | AH13: =IFERROR(AG13/AF13,0) -> 1 | AI13: =AF13-AG13 -> 0 | AJ13: =VLOOKUP(C13,'Giao CT'!$D$6:$S$20,11,0) -> 4 | AK13: 8 | AL13: =200%-IFERROR(AK13/AJ13,0) -> 0 | AM13: =MAX(AL13,0) -> 0 | AN13: =VLOOKUP(C13,'Giao CT'!$D$6:$S$20,12,0) -> 5 | AO13: =VLOOKUP(C13,GBOC!$E$7:$DG$29,$B$29,0) -> 5 | AP13: =200%-IFERROR(AO13/AN13,0) -> 1 | AQ13: =MAX(AP13,0) -> 1 | AR13: 0.97 | AS13: =(VLOOKUP(B13,cuoc!$B$7:$P$27,14,0))*1% -> 0.9605 | AT13: =IF(AS13<94.5%,0,IF(AS13<95.54%,50%,IF(AS13<AR13,80%,100%+(30%*(AS13-AR13)/3.39%)))) -> 0.8 | AU13: =AR13-AS13 -> 0.0095 | AV13: =VLOOKUP(C13,'Giao CT'!$D$6:$S$20,14,0) -> 3 | AW13: =VLOOKUP(C13,GBOC!$E$7:$DG$29,$B$31,0) -> 2 | AX13: =AW13/AV13 -> 0.66666667 | AY13: =AV13-AW13 -> 1 | AZ13: =VLOOKUP(C13,'Giao CT'!$D$6:$S$20,15,0) -> 1 | BA13: =VLOOKUP(C13,GBOC!$E$7:$DG$29,$B$32,0) -> 1 | BB13: =IFERROR(BA13/AZ13,1) -> 1 | BC13: =AZ13-BA13 -> 0 | BD13: =VLOOKUP(C13,'Giao CT'!$D$6:$S$20,16,0) -> 0 | BE13: =VLOOKUP(C13,GBOC!$E$7:$DG$29,$B$33,0) -> 2 | BF13: =IFERROR(BE13/BD13,1) -> 1 | BG13: =BD13-BE13 -> -2
A14: Lê Thanh Sang | B14: SANGLT_LDG_CNKD | C14: CNKD_LDG_SANGLT | D14: =VLOOKUP(C14,'Giao CT'!$D$6:$S$20,3,0) -> 8 | E14: =VLOOKUP(C14,GBOC!$E$7:$DG$29,$B$20,0) -> 8 | F14: =IFERROR(E14/D14,0) -> 1 | G14: =D14-E14 -> 0 | H14: =VLOOKUP(C14,'Giao CT'!$D$6:$S$20,4,0) -> 4 | I14: =VLOOKUP(C14,GBOC!$E$7:$DG$29,$B$21,0) -> 2 | J14: =IFERROR(I14/H14,0) -> 0.5 | K14: =H14-I14 -> 2 | L14: =VLOOKUP(C14,'Giao CT'!$D$6:$S$20,5,0) -> 5 | M14: =VLOOKUP(C14,GBOC!$E$7:$DG$29,$B$22,0) -> 2 | N14: =IFERROR(M14/L14,0) -> 0.4 | O14: =L14-M14 -> 3 | P14: =VLOOKUP(C14,'Giao CT'!$D$6:$S$20,6,0) -> 5 | Q14: =VLOOKUP(C14,GBOC!$E$7:$DG$29,$B$23,0) -> 3 | R14: =IFERROR(Q14/P14,0) -> 0.6 | S14: =P14-Q14 -> 2 | T14: =VLOOKUP(C14,'Giao CT'!$D$6:$S$20,7,0) -> 3 | U14: =VLOOKUP(C14,GBOC!$E$7:$DG$29,$B$24,0) -> 2 | V14: =IFERROR(U14/T14,0) -> 0.66666667 | W14: =T14-U14 -> 1 | X14: =VLOOKUP(C14,'Giao CT'!$D$6:$S$20,8,0) -> 1 | Y14: =VLOOKUP(C14,GBOC!$E$7:$DG$29,$B$25,0) -> 1 | Z14: =IFERROR(Y14/X14,0) -> 1 | AA14: =X14-Y14 -> 0 | AB14: =VLOOKUP(C14,'Giao CT'!$D$6:$S$20,9,0) -> 30 | AC14: =VLOOKUP(C14,GBOC!$E$7:$DG$29,$B$26,0) -> 13 | AD14: =IFERROR(AC14/AB14,0) -> 0.43333333 | AE14: =AB14-AC14 -> 17 | AF14: =VLOOKUP(C14,'Giao CT'!$D$6:$S$20,10,0) -> 9 | AG14: =VLOOKUP(C14,GBOC!$E$7:$DG$29,$B$27,0) -> 10 | AH14: =IFERROR(AG14/AF14,0) -> 1.1111111 | AI14: =AF14-AG14 -> -1 | AJ14: =VLOOKUP(C14,'Giao CT'!$D$6:$S$20,11,0) -> 4 | AK14: 4 | AL14: =200%-IFERROR(AK14/AJ14,0) -> 1 | AM14: =MAX(AL14,0) -> 1 | AN14: =VLOOKUP(C14,'Giao CT'!$D$6:$S$20,12,0) -> 5 | AO14: =VLOOKUP(C14,GBOC!$E$7:$DG$29,$B$29,0) -> 6 | AP14: =200%-IFERROR(AO14/AN14,0) -> 0.8 | AQ14: =MAX(AP14,0) -> 0.8 | AR14: 0.97 | AS14: =(VLOOKUP(B14,cuoc!$B$7:$P$27,14,0))*1% -> 0.9325 | AT14: =IF(AS14<94.5%,0,IF(AS14<95.54%,50%,IF(AS14<AR14,80%,100%+(30%*(AS14-AR14)/3.39%)))) -> 0 | AU14: =AR14-AS14 -> 0.0375 | AV14: =VLOOKUP(C14,'Giao CT'!$D$6:$S$20,14,0) -> 2 | AW14: =VLOOKUP(C14,GBOC!$E$7:$DG$29,$B$31,0) -> 0 | AX14: =AW14/AV14 -> 0 | AY14: =AV14-AW14 -> 2 | AZ14: =VLOOKUP(C14,'Giao CT'!$D$6:$S$20,15,0) -> 1 | BA14: =VLOOKUP(C14,GBOC!$E$7:$DG$29,$B$32,0) -> 1 | BB14: =IFERROR(BA14/AZ14,1) -> 1 | BC14: =AZ14-BA14 -> 0 | BD14: =VLOOKUP(C14,'Giao CT'!$D$6:$S$20,16,0) -> 0 | BE14: =VLOOKUP(C14,GBOC!$E$7:$DG$29,$B$33,0) -> 0 | BF14: =IFERROR(BE14/BD14,1) -> 1 | BG14: =BD14-BE14 -> 0
A15: Trương Văn Sang | B15: SANGTV_LDG_CNKD | C15: CNKD_LDG_SANGTV | D15: =VLOOKUP(C15,'Giao CT'!$D$6:$S$20,3,0) -> 7 | E15: =VLOOKUP(C15,GBOC!$E$7:$DG$29,$B$20,0) -> 7 | F15: =IFERROR(E15/D15,0) -> 1 | G15: =D15-E15 -> 0 | H15: =VLOOKUP(C15,'Giao CT'!$D$6:$S$20,4,0) -> 4 | I15: =VLOOKUP(C15,GBOC!$E$7:$DG$29,$B$21,0) -> 5 | J15: =IFERROR(I15/H15,0) -> 1.25 | K15: =H15-I15 -> -1 | L15: =VLOOKUP(C15,'Giao CT'!$D$6:$S$20,5,0) -> 5 | M15: =VLOOKUP(C15,GBOC!$E$7:$DG$29,$B$22,0) -> 4 | N15: =IFERROR(M15/L15,0) -> 0.8 | O15: =L15-M15 -> 1 | P15: =VLOOKUP(C15,'Giao CT'!$D$6:$S$20,6,0) -> 4 | Q15: =VLOOKUP(C15,GBOC!$E$7:$DG$29,$B$23,0) -> 3 | R15: =IFERROR(Q15/P15,0) -> 0.75 | S15: =P15-Q15 -> 1 | T15: =VLOOKUP(C15,'Giao CT'!$D$6:$S$20,7,0) -> 4 | U15: =VLOOKUP(C15,GBOC!$E$7:$DG$29,$B$24,0) -> 4 | V15: =IFERROR(U15/T15,0) -> 1 | W15: =T15-U15 -> 0 | X15: =VLOOKUP(C15,'Giao CT'!$D$6:$S$20,8,0) -> 1 | Y15: =VLOOKUP(C15,GBOC!$E$7:$DG$29,$B$25,0) -> 1 | Z15: =IFERROR(Y15/X15,0) -> 1 | AA15: =X15-Y15 -> 0 | AB15: =VLOOKUP(C15,'Giao CT'!$D$6:$S$20,9,0) -> 30 | AC15: =VLOOKUP(C15,GBOC!$E$7:$DG$29,$B$26,0) -> 52 | AD15: =IFERROR(AC15/AB15,0) -> 1.7333333 | AE15: =AB15-AC15 -> -22 | AF15: =VLOOKUP(C15,'Giao CT'!$D$6:$S$20,10,0) -> 8 | AG15: =VLOOKUP(C15,GBOC!$E$7:$DG$29,$B$27,0) -> 6 | AH15: =IFERROR(AG15/AF15,0) -> 0.75 | AI15: =AF15-AG15 -> 2 | AJ15: =VLOOKUP(C15,'Giao CT'!$D$6:$S$20,11,0) -> 4 | AK15: 4 | AL15: =200%-IFERROR(AK15/AJ15,0) -> 1 | AM15: =MAX(AL15,0) -> 1 | AN15: =VLOOKUP(C15,'Giao CT'!$D$6:$S$20,12,0) -> 4 | AO15: =VLOOKUP(C15,GBOC!$E$7:$DG$29,$B$29,0) -> 2 | AP15: =200%-IFERROR(AO15/AN15,0) -> 1.5 | AQ15: =MAX(AP15,0) -> 1.5 | AR15: 0.97 | AS15: =(VLOOKUP(B15,cuoc!$B$7:$P$27,14,0))*1% -> 0.9553 | AT15: =IF(AS15<94.5%,0,IF(AS15<95.54%,50%,IF(AS15<AR15,80%,100%+(30%*(AS15-AR15)/3.39%)))) -> 0.5 | AU15: =AR15-AS15 -> 0.0147 | AV15: =VLOOKUP(C15,'Giao CT'!$D$6:$S$20,14,0) -> 2 | AW15: =VLOOKUP(C15,GBOC!$E$7:$DG$29,$B$31,0) -> 0 | AX15: =AW15/AV15 -> 0 | AY15: =AV15-AW15 -> 2 | AZ15: =VLOOKUP(C15,'Giao CT'!$D$6:$S$20,15,0) -> 1 | BA15: =VLOOKUP(C15,GBOC!$E$7:$DG$29,$B$32,0) -> 3 | BB15: =IFERROR(BA15/AZ15,1) -> 3 | BC15: =AZ15-BA15 -> -2 | BD15: =VLOOKUP(C15,'Giao CT'!$D$6:$S$20,16,0) -> 0 | BE15: =VLOOKUP(C15,GBOC!$E$7:$DG$29,$B$33,0) -> 0 | BF15: =IFERROR(BE15/BD15,1) -> 1 | BG15: =BD15-BE15 -> 0
A16: Đặng Thị Tám | B16: TAMDT_LDG_CNKD | C16: CNKD_LDG_TAMDT | D16: =VLOOKUP(C16,'Giao CT'!$D$6:$S$20,3,0) -> 8 | E16: =VLOOKUP(C16,GBOC!$E$7:$DG$29,$B$20,0) -> 8 | F16: =IFERROR(E16/D16,0) -> 1 | G16: =D16-E16 -> 0 | H16: =VLOOKUP(C16,'Giao CT'!$D$6:$S$20,4,0) -> 4 | I16: =VLOOKUP(C16,GBOC!$E$7:$DG$29,$B$21,0) -> 6 | J16: =IFERROR(I16/H16,0) -> 1.5 | K16: =H16-I16 -> -2 | L16: =VLOOKUP(C16,'Giao CT'!$D$6:$S$20,5,0) -> 5 | M16: =VLOOKUP(C16,GBOC!$E$7:$DG$29,$B$22,0) -> 3 | N16: =IFERROR(M16/L16,0) -> 0.6 | O16: =L16-M16 -> 2 | P16: =VLOOKUP(C16,'Giao CT'!$D$6:$S$20,6,0) -> 5 | Q16: =VLOOKUP(C16,GBOC!$E$7:$DG$29,$B$23,0) -> 4 | R16: =IFERROR(Q16/P16,0) -> 0.8 | S16: =P16-Q16 -> 1 | T16: =VLOOKUP(C16,'Giao CT'!$D$6:$S$20,7,0) -> 4 | U16: =VLOOKUP(C16,GBOC!$E$7:$DG$29,$B$24,0) -> 4 | V16: =IFERROR(U16/T16,0) -> 1 | W16: =T16-U16 -> 0 | X16: =VLOOKUP(C16,'Giao CT'!$D$6:$S$20,8,0) -> 1 | Y16: =VLOOKUP(C16,GBOC!$E$7:$DG$29,$B$25,0) -> 2 | Z16: =IFERROR(Y16/X16,0) -> 2 | AA16: =X16-Y16 -> -1 | AB16: =VLOOKUP(C16,'Giao CT'!$D$6:$S$20,9,0) -> 30 | AC16: =VLOOKUP(C16,GBOC!$E$7:$DG$29,$B$26,0) -> 73 | AD16: =IFERROR(AC16/AB16,0) -> 2.4333333 | AE16: =AB16-AC16 -> -43 | AF16: =VLOOKUP(C16,'Giao CT'!$D$6:$S$20,10,0) -> 9 | AG16: =VLOOKUP(C16,GBOC!$E$7:$DG$29,$B$27,0) -> 12 | AH16: =IFERROR(AG16/AF16,0) -> 1.3333333 | AI16: =AF16-AG16 -> -3 | AJ16: =VLOOKUP(C16,'Giao CT'!$D$6:$S$20,11,0) -> 4 | AK16: 4 | AL16: =200%-IFERROR(AK16/AJ16,0) -> 1 | AM16: =MAX(AL16,0) -> 1 | AN16: =VLOOKUP(C16,'Giao CT'!$D$6:$S$20,12,0) -> 5 | AO16: =VLOOKUP(C16,GBOC!$E$7:$DG$29,$B$29,0) -> 3 | AP16: =200%-IFERROR(AO16/AN16,0) -> 1.4 | AQ16: =MAX(AP16,0) -> 1.4 | AR16: 0.97 | AS16: =(VLOOKUP(B16,cuoc!$B$7:$P$27,14,0))*1% -> 0.9585 | AT16: =IF(AS16<94.5%,0,IF(AS16<95.54%,50%,IF(AS16<AR16,80%,100%+(30%*(AS16-AR16)/3.39%)))) -> 0.8 | AU16: =AR16-AS16 -> 0.0115 | AV16: =VLOOKUP(C16,'Giao CT'!$D$6:$S$20,14,0) -> 3 | AW16: =VLOOKUP(C16,GBOC!$E$7:$DG$29,$B$31,0) -> 0 | AX16: =AW16/AV16 -> 0 | AY16: =AV16-AW16 -> 3 | AZ16: =VLOOKUP(C16,'Giao CT'!$D$6:$S$20,15,0) -> 1 | BA16: =VLOOKUP(C16,GBOC!$E$7:$DG$29,$B$32,0) -> 2 | BB16: =IFERROR(BA16/AZ16,1) -> 2 | BC16: =AZ16-BA16 -> -1 | BD16: =VLOOKUP(C16,'Giao CT'!$D$6:$S$20,16,0) -> 0 | BE16: =VLOOKUP(C16,GBOC!$E$7:$DG$29,$B$33,0) -> 2 | BF16: =IFERROR(BE16/BD16,1) -> 1 | BG16: =BD16-BE16 -> -2
... A18: Vòng Vĩnh Vân | B18: VANVV_LDG_CNKD | C18: CNKD_LDG_VANVV | D18: =VLOOKUP(C18,'Giao CT'!$D$6:$S$20,3,0) -> 3 | E18: =VLOOKUP(C18,GBOC!$E$7:$DG$29,$B$20,0) -> 4 | F18: =IFERROR(E18/D18,0) -> 1.3333333 | G18: =D18-E18 -> -1 | H18: =VLOOKUP(C18,'Giao CT'!$D$6:$S$20,4,0) -> 2 | I18: =VLOOKUP(C18,GBOC!$E$7:$DG$29,$B$21,0) -> 0 | J18: =IFERROR(I18/H18,0) -> 0 | K18: =H18-I18 -> 2 | L18: =VLOOKUP(C18,'Giao CT'!$D$6:$S$20,5,0) -> 2 | M18: =VLOOKUP(C18,GBOC!$E$7:$DG$29,$B$22,0) -> 3 | N18: =IFERROR(M18/L18,0) -> 1.5 | O18: =L18-M18 -> -1 | P18: =VLOOKUP(C18,'Giao CT'!$D$6:$S$20,6,0) -> 3 | Q18: =VLOOKUP(C18,GBOC!$E$7:$DG$29,$B$23,0) -> 1 | R18: =IFERROR(Q18/P18,0) -> 0.33333333 | S18: =P18-Q18 -> 2 | T18: =VLOOKUP(C18,'Giao CT'!$D$6:$S$20,7,0) -> 3 | U18: =VLOOKUP(C18,GBOC!$E$7:$DG$29,$B$24,0) -> 3 | V18: =IFERROR(U18/T18,0) -> 1 | W18: =T18-U18 -> 0 | X18: =VLOOKUP(C18,'Giao CT'!$D$6:$S$20,8,0) -> 1 | Y18: =VLOOKUP(C18,GBOC!$E$7:$DG$29,$B$25,0) -> 1 | Z18: =IFERROR(Y18/X18,0) -> 1 | AA18: =X18-Y18 -> 0 | AB18: =VLOOKUP(C18,'Giao CT'!$D$6:$S$20,9,0) -> 14 | AC18: =VLOOKUP(C18,GBOC!$E$7:$DG$29,$B$26,0) -> 21 | AD18: =IFERROR(AC18/AB18,0) -> 1.5 | AE18: =AB18-AC18 -> -7 | AF18: =VLOOKUP(C18,'Giao CT'!$D$6:$S$20,10,0) -> 5 | AG18: =VLOOKUP(C18,GBOC!$E$7:$DG$29,$B$27,0) -> 3 | AH18: =IFERROR(AG18/AF18,0) -> 0.6 | AI18: =AF18-AG18 -> 2 | AJ18: =VLOOKUP(C18,'Giao CT'!$D$6:$S$20,11,0) -> 3 | AK18: 4 | AL18: =200%-IFERROR(AK18/AJ18,0) -> 0.66666667 | AM18: =MAX(AL18,0) -> 0.66666667 | AN18: =VLOOKUP(C18,'Giao CT'!$D$6:$S$20,12,0) -> 3 | AO18: =VLOOKUP(C18,GBOC!$E$7:$DG$29,$B$29,0) -> 0 | AP18: =200%-IFERROR(AO18/AN18,0) -> 2 | AQ18: =MAX(AP18,0) -> 2 | AR18: 0.97 | AS18: =(VLOOKUP(B18,cuoc!$B$7:$P$27,14,0))*1% -> 0.9526 | AT18: =IF(AS18<94.5%,0,IF(AS18<95.54%,50%,IF(AS18<AR18,80%,100%+(30%*(AS18-AR18)/3.39%)))) -> 0.5 | AU18: =AR18-AS18 -> 0.0174 | AV18: =VLOOKUP(C18,'Giao CT'!$D$6:$S$20,14,0) -> 1 | AW18: =VLOOKUP(C18,GBOC!$E$7:$DG$29,$B$31,0) -> 0 | AX18: =AW18/AV18 -> 0 | AY18: =AV18-AW18 -> 1 | AZ18: =VLOOKUP(C18,'Giao CT'!$D$6:$S$20,15,0) -> 1 | BA18: =VLOOKUP(C18,GBOC!$E$7:$DG$29,$B$32,0) -> 1 | BB18: =IFERROR(BA18/AZ18,1) -> 1 | BC18: =AZ18-BA18 -> 0 | BD18: =VLOOKUP(C18,'Giao CT'!$D$6:$S$20,16,0) -> 0 | BE18: =VLOOKUP(C18,GBOC!$E$7:$DG$29,$B$33,0) -> 0 | BF18: =IFERROR(BE18/BD18,1) -> 1 | BG18: =BD18-BE18 -> 0
F19: =TODAY() -> 46081 | I19: =DAY(F19) -> 28 | J19: 31 | K19: =I19/J19 -> 0.90322581 | L19: KPI theo tiến độ ngày | BG19: =#REF!*80%-#REF! -> #REF!
A20: TB FTTH phát triển mới | B20: 7 | C20: =B20-2 -> 5
A21: Supernet PTM | B21: 15 | C21: =B21-2 -> 13
A22: Camera Đấu nối và bán đứt mua icloud | B22: 55 | C22: =B22-2 -> 53
A23: THS Đôi dây PTM | B23: 87 | C23: =B23-2 -> 85
A24: Thuê Bao trả sau | B24: 95 | C24: =B24-2 -> 93
A25: Thuê bao thực 4G | B25: 103 | C25: =B25-2 -> 101
A26: Thuê bao 5G | B26: 47 | C26: =B26-2 -> 45
A27: Thuê bao standard | B27: 79 | C27: =B27-2 -> 77
A28: Rời mạng THS | B28: 39 | C28: =B28-2 -> 37
A29: Rời mạng FTTH | B29: 31 | C29: =B29-2 -> 29
A30: Cước N1- N3
A31: Khôi phục THS | B31: 23 | C31: =B31-2 -> 21
A32: Thuê Bao mybox | B32: 71 | C32: =B32-2 -> 69
A33: MYKID | B33: 63 | C33: =B33-2 -> 61

Sheet điểm NV
A1: STT | B1: Bảng tính điểm cá nhân Kinh doanh
B2: Lê Thanh Sang | C2: KH | D2: TH | E2: Tỷ lệ hoàn thành | F2: Tỷ lệ hoàn thành | G2: Điểm Chuẩn | H2: Điểm tối đa | I2: Điểm Đạt theo chỉ tiêu | J2: Thiếu để đạt 100% | K2: Lưu ý, đỏ là đã dư Mốc 100%. Anh em canh số lượng ô màu vàng để làm
A3: A | B3: CHỈ TIÊU KINH DOANH VTT: | G3: =SUM(G4:G14) -> 101 | H3: =SUM(H4:H14) -> 125.7 | L3: mã dữ liệu ko xoá
A4: 1 | B4: TBTS_PTM (gồm CĐ) | C4: =VLOOKUP($B$2,'TH NV'!$A$5:$BG$18,'điểm NV'!M8,0) -> 3 | D4: =VLOOKUP($B$2,'TH NV'!$A$5:$BG$18,N8,0) -> 2 | E4: =D4/C4 -> 0.66666667 | F4: =MAX(E4,0) -> 0.66666667 | G4: 10 | H4: =G4*1.2 -> 12 | I4: =IF(F4>=1.3,G4*1.3,F4*G4) -> 6.6666667 | J4: =C4-D4 -> 1 | L4: TB FTTH phát triển mới | M4: 4 | N4: =M4+1 -> 5
A5: 2 | B5: Số chu kỳ mua gói 5G: | C5: =VLOOKUP($B$2,'TH NV'!$A$5:$BG$18,'điểm NV'!M10,0) -> 30 | D5: =VLOOKUP($B$2,'TH NV'!$A$5:$BG$18,N10,0) -> 13 | E5: =D5/C5 -> 0.43333333 | F5: =MAX(E5,0) -> 0.43333333 | G5: 10 | H5: =G5*1.3 -> 13 | I5: =IF(F5>=1.2,G5*1.2,F5*G5) -> 4.3333333 | J5: =C5-D5 -> 17 | L5: Supernet PTM | M5: 8 | N5: =M5+1 -> 9
A6: 3 | B6: Thuê bao FTTH phát triển mới | C6: =VLOOKUP($B$2,'TH NV'!$A$5:$BG$18,'điểm NV'!M4,0) -> 8 | D6: =VLOOKUP($B$2,'TH NV'!$A$5:$BG$18,N4,0) -> 8 | E6: =D6/C6 -> 1 | F6: =MAX(E6,0) -> 1 | G6: 15 | H6: =G6*1.3 -> 19.5 | I6: =IF(F6>=1.3,G6*1.3,F6*G6) -> 15 | J6: =C6-D6 -> 0 | L6: Camera Đấu nối và bán đứt mua icloud | M6: 12 | N6: =M6+1 -> 13
A7: 4 | B7: Thuê bao FTTH Supernet PTM và nâng cấp | C7: =VLOOKUP($B$2,'TH NV'!$A$5:$BG$18,'điểm NV'!M5,0) -> 4 | D7: =VLOOKUP($B$2,'TH NV'!$A$5:$BG$18,N5,0) -> 2 | E7: =D7/C7 -> 0.5 | F7: =MAX(E7,0) -> 0.5 | G7: 10 | H7: =G7*1.2 -> 12 | I7: =IF(F7>=1.2,G7*1.2,F7*G7) -> 5 | J7: =C7-D7 -> 2 | L7: THS Đôi dây PTM | M7: 16 | N7: =M7+1 -> 17
A8: 5 | B8: TB Truyền hình MHL phát triển mới trên đôi dây FTTH | C8: =VLOOKUP($B$2,'TH NV'!$A$5:$BG$18,'điểm NV'!M7,0) -> 5 | D8: =VLOOKUP($B$2,'TH NV'!$A$5:$BG$18,N7,0) -> 3 | E8: =(D8/C8) -> 0.6 | F8: =MAX(E8,0) -> 0.6 | G8: 10 | H8: =G8*1.3 -> 13 | I8: =IF(F8>=1.2,G8*1.2,F8*G8) -> 6 | J8: =C8-D8 -> 2 | L8: Thuê Bao trả sau | M8: 20 | N8: =M8+1 -> 21
A9: 6 | B9: TB TH rời mạng cho phép | C9: =VLOOKUP($B$2,'TH NV'!$A$5:$BG$18,'điểm NV'!M12,0) -> 4 | D9: =VLOOKUP($B$2,'TH NV'!$A$5:$BG$18,N12,0) -> 4 | E9: =200%-(D9/C9) -> 1 | F9: =MAX(E9,0) -> 1 | G9: 10 | H9: =G9*1.2 -> 12 | I9: =IF(F9>=1.2,G9*1.2,F9*G9) -> 10 | J9: =C9-D9 -> 0 | L9: Thuê bao thực 4G | M9: 24 | N9: =M9+1 -> 25
A10: 7 | B10: TB FTTH Rời mạng | C10: =VLOOKUP($B$2,'TH NV'!$A$5:$BG$18,'điểm NV'!M13,0) -> 5 | D10: =VLOOKUP($B$2,'TH NV'!$A$5:$BG$18,N13,0) -> 6 | E10: =200%-IFERROR(D10/C10,2) -> 0.8 | F10: =MAX(E10,0) -> 0.8 | G10: 10 | H10: =G10*1.2 -> 12 | I10: =IF(F10>=1.2,G10*1.2,F10*G10) -> 8 | J10: =C10-D10 -> -1 | L10: Thuê bao 5G | M10: 28 | N10: =M10+1 -> 29
A11: 8 | B11: TB TH TV360 MHN Phát triển mới | C11: =VLOOKUP($B$2,'TH NV'!$A$5:$BG$18,'điểm NV'!M11,0) -> 9 | D11: =VLOOKUP($B$2,'TH NV'!$A$5:$BG$18,N11,0) -> 10 | E11: =D11/C11 -> 1.1111111 | F11: =MAX(E11,0) -> 1.1111111 | G11: 5 | H11: =G11*1.2 -> 6 | I11: =IF(F11>=1.2,G11*1.2,F11*G11) -> 5.5555556 | J11: =C11-D11 -> -1 | L11: Thuê bao standard | M11: 32 | N11: =M11+1 -> 33
A12: 9 | B12: Mybox | C12: =VLOOKUP($B$2,'TH NV'!$A$5:$BG$18,'điểm NV'!M16,0) -> 1 | D12: =VLOOKUP($B$2,'TH NV'!$A$5:$BG$18,N16,0) -> 1 | F12: =MAX(E12,0) -> 0 | G12: 1 | H12: =G12*1.2 -> 1.2 | I12: =IF(F12>=1.2,G12*1.2,F12*G12) -> 0 | J12: =C12-D12 -> 0 | L12: Rời mạng THS | M12: 36 | N12: =M12+1 -> 37
A13: 10 | B13: Sản lượng Thuê bao IOT HGĐ | C13: =VLOOKUP($B$2,'TH NV'!$A$5:$BG$18,'điểm NV'!M6,0)+VLOOKUP($B$2,'TH NV'!$A$5:$BG$18,'điểm NV'!M17,0) -> 5 | D13: =VLOOKUP($B$2,'TH NV'!$A$5:$BG$18,N6,0)+VLOOKUP($B$2,'TH NV'!$A$5:$BG$18,N17,0) -> 2 | E13: =D13/C13 -> 0.4 | F13: =MAX(E13,0) -> 0.4 | G13: 10 | H13: =G13*1.2 -> 12 | I13: =IF(F13>=1.2,G13*1.2,F13*G13) -> 4 | J13: =C13-D13 -> 3 | L13: Rời mạng FTTH | M13: 40 | N13: =M13+1 -> 41
A14: 11 | B14: Tỷ lệ thu cước trả sau N1-N3 | C14: 0.97 | D14: =VLOOKUP($B$2,'TH NV'!$A$5:$BG$18,N14,0) -> 0.9325 | E14: =VLOOKUP($B$2,'TH NV'!$A$1:$BG$18,70,0) -> #REF! | F14: =IF(D14<94.5%,0,IF(D14<95.54%,50%,IF(D14<C14,80%,100%+(30%*(D14-C14)/3.66%)))) -> 0 | G14: 10 | H14: =G14*1.3 -> 13 | I14: =IF(F14>=1.3,G14*1.3,F14*G14) -> 0 | J14: =C14-D14 -> 0.0375 | L14: Cước N1- N3 | N14: 45
B15: Tô vàng 130% | C15: Tổng Điểm hoàn thành | I15: =SUM(I4:I14) -> 64.555556 | L15: Khôi phục THS | M15: 48 | N15: =M15+1 -> 49
L16: Thuê Bao mybox | M16: 52 | N16: =M16+1 -> 53
L17: MYKID | M17: 56 | N17: =M17+1 -> 57

Sheet tiến độ
D1: Dịch vụ cố định | T1: Dịch vụ di động | AJ1: CHỈ TIÊU CƯỚC - CSKH | AV1: CHƯƠNG TRÌNH TRỌNG ĐIỂM
D2: TB FTTH phát triển mới | H2: Supernet PTM | L2: Camera Đấu nối và bán đứt mua icloud | P2: THS Đôi dây PTM | T2: Thuê Bao trả sau | X2: Thuê bao thực 4G | AB2: Thuê bao 5G | AF2: Thuê bao standard | AJ2: Rời mạng THS | AN2: Rời mạng FTTH | AR2: Cước N1- N3 | AV2: Khôi phục THS | AZ2: Thuê Bao mybox | BD2: MYKID
B3: USER CNKD | C3: NV Quản Lý | D3: KH | E3: TH | F3: % | G3: Thiếu | H3: KH | I3: TH | J3: % | K3: Thiếu | L3: KH | M3: TH | N3: % | O3: Thiếu | P3: KH | Q3: TH | R3: % | S3: Thiếu | T3: KH | U3: TH | V3: % | W3: Thiếu | X3: KH | Y3: TH | Z3: % | AA3: Thiếu | AB3: KH | AC3: TH | AD3: % | AE3: Thiếu | AF3: KH | AG3: TH | AH3: % | AI3: Thiếu | AJ3: KH | AK3: TH | AL3: % | AM3: còn được | AN3: KH | AO3: TH | AP3: % | AQ3: còn được | AR3: KH | AS3: TH | AT3: ĐẠT | AU3: thiếu | AV3: KH | AW3: TH | AX3: % | AY3: Thiếu | AZ3: KH | BA3: TH | BB3: % | BC3: Thiếu | BD3: KH | BE3: TH | BF3: % | BG3: Thiếu
A4: CNKD_LDG_ANLT | B4: ANLT_LDG_CNKD | C4: VIETDQ9_NVKDDB_LDG | D4: =VLOOKUP(A4,'Giao CT'!$D$6:$S$20,3,0) -> 8 | E4: =VLOOKUP(A4,GBOC!$E$7:$DG$29,$B$21,0) -> 8 | F4: =IFERROR(E4/D4,0) -> 1 | G4: =D4-E4 -> 0 | H4: =VLOOKUP(A4,'Giao CT'!$D$6:$S$20,4,0) -> 4 | I4: =VLOOKUP(A4,GBOC!$E$7:$DG$29,$B$22,0) -> 6 | J4: =IFERROR(I4/H4,0) -> 1.5 | K4: =H4-I4 -> -2 | L4: =VLOOKUP(A4,'Giao CT'!$D$6:$S$20,5,0) -> 5 | M4: =VLOOKUP(A4,GBOC!$E$7:$DG$29,$B$23,0) -> 5 | N4: =IFERROR(M4/L4,0) -> 1 | O4: =L4-M4 -> 0 | P4: =VLOOKUP(A4,'Giao CT'!$D$6:$S$20,6,0) -> 5 | Q4: =VLOOKUP(A4,GBOC!$E$7:$DG$29,$B$24,0) -> 6 | R4: =IFERROR(Q4/P4,0) -> 1.2 | S4: =P4-Q4 -> -1 | T4: =VLOOKUP(A4,'Giao CT'!$D$6:$S$20,7,0) -> 4 | U4: =VLOOKUP(A4,GBOC!$E$7:$DG$29,$B$25,0) -> 4 | V4: =IFERROR(U4/T4,0) -> 1 | W4: =T4-U4 -> 0 | X4: =VLOOKUP(A4,'Giao CT'!$D$6:$S$20,8,0) -> 1 | Y4: =VLOOKUP(A4,GBOC!$E$7:$DG$29,$B$26,0) -> 1 | Z4: =IFERROR(Y4/X4,0) -> 1 | AA4: =X4-Y4 -> 0 | AB4: =VLOOKUP(A4,'Giao CT'!$D$6:$S$20,9,0) -> 30 | AC4: =VLOOKUP(A4,GBOC!$E$7:$DG$29,$B$27,0) -> 33 | AD4: =IFERROR(AC4/AB4,0) -> 1.1 | AE4: =AB4-AC4 -> -3 | AF4: =VLOOKUP(A4,'Giao CT'!$D$6:$S$20,10,0) -> 9 | AG4: =VLOOKUP(A4,GBOC!$E$7:$DG$29,$B$28,0) -> 12 | AH4: =IFERROR(AG4/AF4,0) -> 1.3333333 | AI4: =AF4-AG4 -> -3 | AJ4: =VLOOKUP(A4,'Giao CT'!$D$6:$S$20,11,0) -> 4 | AK4: =VLOOKUP(B4,'TH NV'!$B$5:$BG$18,36,0) -> 2 | AL4: =200%-IFERROR(AK4/AJ4,0) -> 1.5 | AM4: =MAX(AL4,0) -> 1.5 | AN4: =VLOOKUP(A4,'Giao CT'!$D$6:$S$20,12,0) -> 5 | AO4: =VLOOKUP(A4,GBOC!$E$7:$DG$29,$B$30,0) -> 3 | AP4: =200%-IFERROR(AO4/AN4,0) -> 1.4 | AQ4: =MAX(AP4,0) -> 1.4 | AR4: 0.97 | AS4: =(VLOOKUP(B4,cuoc!$B$7:$P$27,14,0))*1% -> 0.9641 | AT4: =IF(AS4<94.5%,0,IF(AS4<95.54%,50%,IF(AS4<AR4,80%,100%+(30%*(AS4-AR4)/3.39%)))) -> 0.8 | AU4: =AR4-AS4 -> 0.0059 | AV4: =VLOOKUP(A4,'Giao CT'!$D$6:$S$20,14,0) -> 2 | AW4: =VLOOKUP(A4,GBOC!$E$7:$DG$29,$B$32,0) -> 0 | AX4: =AW4/AV4 -> 0 | AY4: =AV4-AW4 -> 2 | AZ4: =VLOOKUP(A4,'Giao CT'!$D$6:$S$20,15,0) -> 1 | BA4: =VLOOKUP(A4,GBOC!$E$7:$DG$29,$B$33,0) -> 1 | BB4: =IFERROR(BA4/AZ4,1) -> 1 | BC4: =AZ4-BA4 -> 0 | BD4: =VLOOKUP(A4,'Giao CT'!$D$6:$S$20,16,0) -> 0 | BE4: =VLOOKUP(A4,GBOC!$E$7:$DG$29,$B$34,0) -> 0 | BF4: =IFERROR(BE4/BD4,1) -> 1 | BG4: =BD4-BE4 -> 0
A5: CNKD_LDG_LINHPM | B5: LINHPM_LDG_CNKD | C5: VIETDQ9_NVKDDB_LDG | D5: =VLOOKUP(A5,'Giao CT'!$D$6:$S$20,3,0) -> 8 | E5: =VLOOKUP(A5,GBOC!$E$7:$DG$29,$B$21,0) -> 8 | F5: =IFERROR(E5/D5,0) -> 1 | G5: =D5-E5 -> 0 | H5: =VLOOKUP(A5,'Giao CT'!$D$6:$S$20,4,0) -> 4 | I5: =VLOOKUP(A5,GBOC!$E$7:$DG$29,$B$22,0) -> 5 | J5: =IFERROR(I5/H5,0) -> 1.25 | K5: =H5-I5 -> -1 | L5: =VLOOKUP(A5,'Giao CT'!$D$6:$S$20,5,0) -> 5 | M5: =VLOOKUP(A5,GBOC!$E$7:$DG$29,$B$23,0) -> 4 | N5: =IFERROR(M5/L5,0) -> 0.8 | O5: =L5-M5 -> 1 | P5: =VLOOKUP(A5,'Giao CT'!$D$6:$S$20,6,0) -> 5 | Q5: =VLOOKUP(A5,GBOC!$E$7:$DG$29,$B$24,0) -> 1 | R5: =IFERROR(Q5/P5,0) -> 0.2 | S5: =P5-Q5 -> 4 | T5: =VLOOKUP(A5,'Giao CT'!$D$6:$S$20,7,0) -> 4 | U5: =VLOOKUP(A5,GBOC!$E$7:$DG$29,$B$25,0) -> 5 | V5: =IFERROR(U5/T5,0) -> 1.25 | W5: =T5-U5 -> -1 | X5: =VLOOKUP(A5,'Giao CT'!$D$6:$S$20,8,0) -> 1 | Y5: =VLOOKUP(A5,GBOC!$E$7:$DG$29,$B$26,0) -> 1 | Z5: =IFERROR(Y5/X5,0) -> 1 | AA5: =X5-Y5 -> 0 | AB5: =VLOOKUP(A5,'Giao CT'!$D$6:$S$20,9,0) -> 50 | AC5: =VLOOKUP(A5,GBOC!$E$7:$DG$29,$B$27,0) -> 71 | AD5: =IFERROR(AC5/AB5,0) -> 1.42 | AE5: =AB5-AC5 -> -21 | AF5: =VLOOKUP(A5,'Giao CT'!$D$6:$S$20,10,0) -> 9 | AG5: =VLOOKUP(A5,GBOC!$E$7:$DG$29,$B$28,0) -> 11 | AH5: =IFERROR(AG5/AF5,0) -> 1.2222222 | AI5: =AF5-AG5 -> -2 | AJ5: =VLOOKUP(A5,'Giao CT'!$D$6:$S$20,11,0) -> 4 | AK5: =VLOOKUP(B5,'TH NV'!$B$5:$BG$18,36,0) -> 19 | AL5: =200%-IFERROR(AK5/AJ5,0) -> -2.75 | AM5: =MAX(AL5,0) -> 0 | AN5: =VLOOKUP(A5,'Giao CT'!$D$6:$S$20,12,0) -> 5 | AO5: =VLOOKUP(A5,GBOC!$E$7:$DG$29,$B$30,0) -> 2 | AP5: =200%-IFERROR(AO5/AN5,0) -> 1.6 | AQ5: =MAX(AP5,0) -> 1.6 | AR5: 0.97 | AS5: =(VLOOKUP(B5,cuoc!$B$7:$P$27,14,0))*1% -> 0.959 | AT5: =IF(AS5<94.5%,0,IF(AS5<95.54%,50%,IF(AS5<AR5,80%,100%+(30%*(AS5-AR5)/3.39%)))) -> 0.8 | AU5: =AR5-AS5 -> 0.011 | AV5: =VLOOKUP(A5,'Giao CT'!$D$6:$S$20,14,0) -> 2 | AW5: =VLOOKUP(A5,GBOC!$E$7:$DG$29,$B$32,0) -> 0 | AX5: =AW5/AV5 -> 0 | AY5: =AV5-AW5 -> 2 | AZ5: =VLOOKUP(A5,'Giao CT'!$D$6:$S$20,15,0) -> 1 | BA5: =VLOOKUP(A5,GBOC!$E$7:$DG$29,$B$33,0) -> 2 | BB5: =IFERROR(BA5/AZ5,1) -> 2 | BC5: =AZ5-BA5 -> -1 | BD5: =VLOOKUP(A5,'Giao CT'!$D$6:$S$20,16,0) -> 1 | BE5: =VLOOKUP(A5,GBOC!$E$7:$DG$29,$B$34,0) -> 0 | BF5: =IFERROR(BE5/BD5,1) -> 0 | BG5: =BD5-BE5 -> 1
A6: CNKD_LDG_NHUANVD | B6: NHUANVD_LDG_CNKD | C6: VIETDQ9_NVKDDB_LDG | D6: =VLOOKUP(A6,'Giao CT'!$D$6:$S$20,3,0) -> 8 | E6: =VLOOKUP(A6,GBOC!$E$7:$DG$29,$B$21,0) -> 10 | F6: =IFERROR(E6/D6,0) -> 1.25 | G6: =D6-E6 -> -2 | H6: =VLOOKUP(A6,'Giao CT'!$D$6:$S$20,4,0) -> 4 | I6: =VLOOKUP(A6,GBOC!$E$7:$DG$29,$B$22,0) -> 4 | J6: =IFERROR(I6/H6,0) -> 1 | K6: =H6-I6 -> 0 | L6: =VLOOKUP(A6,'Giao CT'!$D$6:$S$20,5,0) -> 5 | M6: =VLOOKUP(A6,GBOC!$E$7:$DG$29,$B$23,0) -> 3 | N6: =IFERROR(M6/L6,0) -> 0.6 | O6: =L6-M6 -> 2 | P6: =VLOOKUP(A6,'Giao CT'!$D$6:$S$20,6,0) -> 5 | Q6: =VLOOKUP(A6,GBOC!$E$7:$DG$29,$B$24,0) -> 6 | R6: =IFERROR(Q6/P6,0) -> 1.2 | S6: =P6-Q6 -> -1 | T6: =VLOOKUP(A6,'Giao CT'!$D$6:$S$20,7,0) -> 3 | U6: =VLOOKUP(A6,GBOC!$E$7:$DG$29,$B$25,0) -> 4 | V6: =IFERROR(U6/T6,0) -> 1.3333333 | W6: =T6-U6 -> -1 | X6: =VLOOKUP(A6,'Giao CT'!$D$6:$S$20,8,0) -> 1 | Y6: =VLOOKUP(A6,GBOC!$E$7:$DG$29,$B$26,0) -> 1 | Z6: =IFERROR(Y6/X6,0) -> 1 | AA6: =X6-Y6 -> 0 | AB6: =VLOOKUP(A6,'Giao CT'!$D$6:$S$20,9,0) -> 30 | AC6: =VLOOKUP(A6,GBOC!$E$7:$DG$29,$B$27,0) -> 61 | AD6: =IFERROR(AC6/AB6,0) -> 2.0333333 | AE6: =AB6-AC6 -> -31 | AF6: =VLOOKUP(A6,'Giao CT'!$D$6:$S$20,10,0) -> 9 | AG6: =VLOOKUP(A6,GBOC!$E$7:$DG$29,$B$28,0) -> 11 | AH6: =IFERROR(AG6/AF6,0) -> 1.2222222 | AI6: =AF6-AG6 -> -2 | AJ6: =VLOOKUP(A6,'Giao CT'!$D$6:$S$20,11,0) -> 4 | AK6: =VLOOKUP(B6,'TH NV'!$B$5:$BG$18,36,0) -> 4 | AL6: =200%-IFERROR(AK6/AJ6,0) -> 1 | AM6: =MAX(AL6,0) -> 1 | AN6: =VLOOKUP(A6,'Giao CT'!$D$6:$S$20,12,0) -> 5 | AO6: =VLOOKUP(A6,GBOC!$E$7:$DG$29,$B$30,0) -> 2 | AP6: =200%-IFERROR(AO6/AN6,0) -> 1.6 | AQ6: =MAX(AP6,0) -> 1.6 | AR6: 0.97 | AS6: =(VLOOKUP(B6,cuoc!$B$7:$P$27,14,0))*1% -> 0.9592 | AT6: =IF(AS6<94.5%,0,IF(AS6<95.54%,50%,IF(AS6<AR6,80%,100%+(30%*(AS6-AR6)/3.39%)))) -> 0.8 | AU6: =AR6-AS6 -> 0.0108 | AV6: =VLOOKUP(A6,'Giao CT'!$D$6:$S$20,14,0) -> 3 | AW6: =VLOOKUP(A6,GBOC!$E$7:$DG$29,$B$32,0) -> 0 | AX6: =AW6/AV6 -> 0 | AY6: =AV6-AW6 -> 3 | AZ6: =VLOOKUP(A6,'Giao CT'!$D$6:$S$20,15,0) -> 1 | BA6: =VLOOKUP(A6,GBOC!$E$7:$DG$29,$B$33,0) -> 1 | BB6: =IFERROR(BA6/AZ6,1) -> 1 | BC6: =AZ6-BA6 -> 0 | BD6: =VLOOKUP(A6,'Giao CT'!$D$6:$S$20,16,0) -> 0 | BE6: =VLOOKUP(A6,GBOC!$E$7:$DG$29,$B$34,0) -> 0 | BF6: =IFERROR(BE6/BD6,1) -> 1 | BG6: =BD6-BE6 -> 0
A7: CNKD_LDG_SANGLT | B7: SANGLT_LDG_CNKD | C7: VIETDQ9_NVKDDB_LDG | D7: =VLOOKUP(A7,'Giao CT'!$D$6:$S$20,3,0) -> 8 | E7: =VLOOKUP(A7,GBOC!$E$7:$DG$29,$B$21,0) -> 8 | F7: =IFERROR(E7/D7,0) -> 1 | G7: =D7-E7 -> 0 | H7: =VLOOKUP(A7,'Giao CT'!$D$6:$S$20,4,0) -> 4 | I7: =VLOOKUP(A7,GBOC!$E$7:$DG$29,$B$22,0) -> 2 | J7: =IFERROR(I7/H7,0) -> 0.5 | K7: =H7-I7 -> 2 | L7: =VLOOKUP(A7,'Giao CT'!$D$6:$S$20,5,0) -> 5 | M7: =VLOOKUP(A7,GBOC!$E$7:$DG$29,$B$23,0) -> 2 | N7: =IFERROR(M7/L7,0) -> 0.4 | O7: =L7-M7 -> 3 | P7: =VLOOKUP(A7,'Giao CT'!$D$6:$S$20,6,0) -> 5 | Q7: =VLOOKUP(A7,GBOC!$E$7:$DG$29,$B$24,0) -> 3 | R7: =IFERROR(Q7/P7,0) -> 0.6 | S7: =P7-Q7 -> 2 | T7: =VLOOKUP(A7,'Giao CT'!$D$6:$S$20,7,0) -> 3 | U7: =VLOOKUP(A7,GBOC!$E$7:$DG$29,$B$25,0) -> 2 | V7: =IFERROR(U7/T7,0) -> 0.66666667 | W7: =T7-U7 -> 1 | X7: =VLOOKUP(A7,'Giao CT'!$D$6:$S$20,8,0) -> 1 | Y7: =VLOOKUP(A7,GBOC!$E$7:$DG$29,$B$26,0) -> 1 | Z7: =IFERROR(Y7/X7,0) -> 1 | AA7: =X7-Y7 -> 0 | AB7: =VLOOKUP(A7,'Giao CT'!$D$6:$S$20,9,0) -> 30 | AC7: =VLOOKUP(A7,GBOC!$E$7:$DG$29,$B$27,0) -> 13 | AD7: =IFERROR(AC7/AB7,0) -> 0.43333333 | AE7: =AB7-AC7 -> 17 | AF7: =VLOOKUP(A7,'Giao CT'!$D$6:$S$20,10,0) -> 9 | AG7: =VLOOKUP(A7,GBOC!$E$7:$DG$29,$B$28,0) -> 10 | AH7: =IFERROR(AG7/AF7,0) -> 1.1111111 | AI7: =AF7-AG7 -> -1 | AJ7: =VLOOKUP(A7,'Giao CT'!$D$6:$S$20,11,0) -> 4 | AK7: =VLOOKUP(B7,'TH NV'!$B$5:$BG$18,36,0) -> 4 | AL7: =200%-IFERROR(AK7/AJ7,0) -> 1 | AM7: =MAX(AL7,0) -> 1 | AN7: =VLOOKUP(A7,'Giao CT'!$D$6:$S$20,12,0) -> 5 | AO7: =VLOOKUP(A7,GBOC!$E$7:$DG$29,$B$30,0) -> 6 | AP7: =200%-IFERROR(AO7/AN7,0) -> 0.8 | AQ7: =MAX(AP7,0) -> 0.8 | AR7: 0.97 | AS7: =(VLOOKUP(B7,cuoc!$B$7:$P$27,14,0))*1% -> 0.9325 | AT7: =IF(AS7<94.5%,0,IF(AS7<95.54%,50%,IF(AS7<AR7,80%,100%+(30%*(AS7-AR7)/3.39%)))) -> 0 | AU7: =AR7-AS7 -> 0.0375 | AV7: =VLOOKUP(A7,'Giao CT'!$D$6:$S$20,14,0) -> 2 | AW7: =VLOOKUP(A7,GBOC!$E$7:$DG$29,$B$32,0) -> 0 | AX7: =AW7/AV7 -> 0 | AY7: =AV7-AW7 -> 2 | AZ7: =VLOOKUP(A7,'Giao CT'!$D$6:$S$20,15,0) -> 1 | BA7: =VLOOKUP(A7,GBOC!$E$7:$DG$29,$B$33,0) -> 1 | BB7: =IFERROR(BA7/AZ7,1) -> 1 | BC7: =AZ7-BA7 -> 0 | BD7: =VLOOKUP(A7,'Giao CT'!$D$6:$S$20,16,0) -> 0 | BE7: =VLOOKUP(A7,GBOC!$E$7:$DG$29,$B$34,0) -> 0 | BF7: =IFERROR(BE7/BD7,1) -> 1 | BG7: =BD7-BE7 -> 0
A8: CNKD_LDG_TAMDT | B8: TAMDT_LDG_CNKD | C8: VIETDQ9_NVKDDB_LDG | D8: =VLOOKUP(A8,'Giao CT'!$D$6:$S$20,3,0) -> 8 | E8: =VLOOKUP(A8,GBOC!$E$7:$DG$29,$B$21,0) -> 8 | F8: =IFERROR(E8/D8,0) -> 1 | G8: =D8-E8 -> 0 | H8: =VLOOKUP(A8,'Giao CT'!$D$6:$S$20,4,0) -> 4 | I8: =VLOOKUP(A8,GBOC!$E$7:$DG$29,$B$22,0) -> 6 | J8: =IFERROR(I8/H8,0) -> 1.5 | K8: =H8-I8 -> -2 | L8: =VLOOKUP(A8,'Giao CT'!$D$6:$S$20,5,0) -> 5 | M8: =VLOOKUP(A8,GBOC!$E$7:$DG$29,$B$23,0) -> 3 | N8: =IFERROR(M8/L8,0) -> 0.6 | O8: =L8-M8 -> 2 | P8: =VLOOKUP(A8,'Giao CT'!$D$6:$S$20,6,0) -> 5 | Q8: =VLOOKUP(A8,GBOC!$E$7:$DG$29,$B$24,0) -> 4 | R8: =IFERROR(Q8/P8,0) -> 0.8 | S8: =P8-Q8 -> 1 | T8: =VLOOKUP(A8,'Giao CT'!$D$6:$S$20,7,0) -> 4 | U8: =VLOOKUP(A8,GBOC!$E$7:$DG$29,$B$25,0) -> 4 | V8: =IFERROR(U8/T8,0) -> 1 | W8: =T8-U8 -> 0 | X8: =VLOOKUP(A8,'Giao CT'!$D$6:$S$20,8,0) -> 1 | Y8: =VLOOKUP(A8,GBOC!$E$7:$DG$29,$B$26,0) -> 2 | Z8: =IFERROR(Y8/X8,0) -> 2 | AA8: =X8-Y8 -> -1 | AB8: =VLOOKUP(A8,'Giao CT'!$D$6:$S$20,9,0) -> 30 | AC8: =VLOOKUP(A8,GBOC!$E$7:$DG$29,$B$27,0) -> 73 | AD8: =IFERROR(AC8/AB8,0) -> 2.4333333 | AE8: =AB8-AC8 -> -43 | AF8: =VLOOKUP(A8,'Giao CT'!$D$6:$S$20,10,0) -> 9 | AG8: =VLOOKUP(A8,GBOC!$E$7:$DG$29,$B$28,0) -> 12 | AH8: =IFERROR(AG8/AF8,0) -> 1.3333333 | AI8: =AF8-AG8 -> -3 | AJ8: =VLOOKUP(A8,'Giao CT'!$D$6:$S$20,11,0) -> 4 | AK8: =VLOOKUP(B8,'TH NV'!$B$5:$BG$18,36,0) -> 4 | AL8: =200%-IFERROR(AK8/AJ8,0) -> 1 | AM8: =MAX(AL8,0) -> 1 | AN8: =VLOOKUP(A8,'Giao CT'!$D$6:$S$20,12,0) -> 5 | AO8: =VLOOKUP(A8,GBOC!$E$7:$DG$29,$B$30,0) -> 3 | AP8: =200%-IFERROR(AO8/AN8,0) -> 1.4 | AQ8: =MAX(AP8,0) -> 1.4 | AR8: 0.97 | AS8: =(VLOOKUP(B8,cuoc!$B$7:$P$27,14,0))*1% -> 0.9585 | AT8: =IF(AS8<94.5%,0,IF(AS8<95.54%,50%,IF(AS8<AR8,80%,100%+(30%*(AS8-AR8)/3.39%)))) -> 0.8 | AU8: =AR8-AS8 -> 0.0115 | AV8: =VLOOKUP(A8,'Giao CT'!$D$6:$S$20,14,0) -> 3 | AW8: =VLOOKUP(A8,GBOC!$E$7:$DG$29,$B$32,0) -> 0 | AX8: =AW8/AV8 -> 0 | AY8: =AV8-AW8 -> 3 | AZ8: =VLOOKUP(A8,'Giao CT'!$D$6:$S$20,15,0) -> 1 | BA8: =VLOOKUP(A8,GBOC!$E$7:$DG$29,$B$33,0) -> 2 | BB8: =IFERROR(BA8/AZ8,1) -> 2 | BC8: =AZ8-BA8 -> -1 | BD8: =VLOOKUP(A8,'Giao CT'!$D$6:$S$20,16,0) -> 0 | BE8: =VLOOKUP(A8,GBOC!$E$7:$DG$29,$B$34,0) -> 2 | BF8: =IFERROR(BE8/BD8,1) -> 1 | BG8: =BD8-BE8 -> -2
A10: CNKD_LDG_HANGBT | B10: HANGBT_LDG_CNKD | C10: SONTV10_NVKDDB_LDG | D10: =VLOOKUP(A10,'Giao CT'!$D$6:$S$20,3,0) -> 7 | E10: =VLOOKUP(A10,GBOC!$E$7:$DG$29,$B$21,0) -> 13 | F10: =IFERROR(E10/D10,0) -> 1.8571429 | G10: =D10-E10 -> -6 | H10: =VLOOKUP(A10,'Giao CT'!$D$6:$S$20,4,0) -> 4 | I10: =VLOOKUP(A10,GBOC!$E$7:$DG$29,$B$22,0) -> 5 | J10: =IFERROR(I10/H10,0) -> 1.25 | K10: =H10-I10 -> -1 | L10: =VLOOKUP(A10,'Giao CT'!$D$6:$S$20,5,0) -> 5 | M10: =VLOOKUP(A10,GBOC!$E$7:$DG$29,$B$23,0) -> 5 | N10: =IFERROR(M10/L10,0) -> 1 | O10: =L10-M10 -> 0 | P10: =VLOOKUP(A10,'Giao CT'!$D$6:$S$20,6,0) -> 4 | Q10: =VLOOKUP(A10,GBOC!$E$7:$DG$29,$B$24,0) -> 7 | R10: =IFERROR(Q10/P10,0) -> 1.75 | S10: =P10-Q10 -> -3 | T10: =VLOOKUP(A10,'Giao CT'!$D$6:$S$20,7,0) -> 4 | U10: =VLOOKUP(A10,GBOC!$E$7:$DG$29,$B$25,0) -> 4 | V10: =IFERROR(U10/T10,0) -> 1 | W10: =T10-U10 -> 0 | X10: =VLOOKUP(A10,'Giao CT'!$D$6:$S$20,8,0) -> 1 | Y10: =VLOOKUP(A10,GBOC!$E$7:$DG$29,$B$26,0) -> 6 | Z10: =IFERROR(Y10/X10,0) -> 6 | AA10: =X10-Y10 -> -5 | AB10: =VLOOKUP(A10,'Giao CT'!$D$6:$S$20,9,0) -> 30 | AC10: =VLOOKUP(A10,GBOC!$E$7:$DG$29,$B$27,0) -> 71 | AD10: =IFERROR(AC10/AB10,0) -> 2.3666667 | AE10: =AB10-AC10 -> -41 | AF10: =VLOOKUP(A10,'Giao CT'!$D$6:$S$20,10,0) -> 8 | AG10: =VLOOKUP(A10,GBOC!$E$7:$DG$29,$B$28,0) -> 10 | AH10: =IFERROR(AG10/AF10,0) -> 1.25 | AI10: =AF10-AG10 -> -2 | AJ10: =VLOOKUP(A10,'Giao CT'!$D$6:$S$20,11,0) -> 4 | AK10: =VLOOKUP(B10,'TH NV'!$B$5:$BG$18,36,0) -> 9 | AL10: =200%-IFERROR(AK10/AJ10,0) -> -0.25 | AM10: =MAX(AL10,0) -> 0 | AN10: =VLOOKUP(A10,'Giao CT'!$D$6:$S$20,12,0) -> 5 | AO10: =VLOOKUP(A10,GBOC!$E$7:$DG$29,$B$30,0) -> 5 | AP10: =200%-IFERROR(AO10/AN10,0) -> 1 | AQ10: =MAX(AP10,0) -> 1 | AR10: 0.97 | AS10: =(VLOOKUP(B10,cuoc!$B$7:$P$27,14,0))*1% -> 0.9605 | AT10: =IF(AS10<94.5%,0,IF(AS10<95.54%,50%,IF(AS10<AR10,80%,100%+(30%*(AS10-AR10)/3.39%)))) -> 0.8 | AU10: =AR10-AS10 -> 0.0095 | AV10: =VLOOKUP(A10,'Giao CT'!$D$6:$S$20,14,0) -> 3 | AW10: =VLOOKUP(A10,GBOC!$E$7:$DG$29,$B$32,0) -> 0 | AX10: =AW10/AV10 -> 0 | AY10: =AV10-AW10 -> 3 | AZ10: =VLOOKUP(A10,'Giao CT'!$D$6:$S$20,15,0) -> 1 | BA10: =VLOOKUP(A10,GBOC!$E$7:$DG$29,$B$33,0) -> 1 | BB10: =IFERROR(BA10/AZ10,1) -> 1 | BC10: =AZ10-BA10 -> 0 | BD10: =VLOOKUP(A10,'Giao CT'!$D$6:$S$20,16,0) -> 1 | BE10: =VLOOKUP(A10,GBOC!$E$7:$DG$29,$B$34,0) -> 0 | BF10: =IFERROR(BE10/BD10,1) -> 0 | BG10: =BD10-BE10 -> 1
A11: CNKD_LDG_HIEUBT | B11: HIEUBT_LDG_CNKD | C11: SONTV10_NVKDDB_LDG | D11: =VLOOKUP(A11,'Giao CT'!$D$6:$S$20,3,0) -> 7 | E11: =VLOOKUP(A11,GBOC!$E$7:$DG$29,$B$21,0) -> 12 | F11: =IFERROR(E11/D11,0) -> 1.7142857 | G11: =D11-E11 -> -5 | H11: =VLOOKUP(A11,'Giao CT'!$D$6:$S$20,4,0) -> 4 | I11: =VLOOKUP(A11,GBOC!$E$7:$DG$29,$B$22,0) -> 4 | J11: =IFERROR(I11/H11,0) -> 1 | K11: =H11-I11 -> 0 | L11: =VLOOKUP(A11,'Giao CT'!$D$6:$S$20,5,0) -> 5 | M11: =VLOOKUP(A11,GBOC!$E$7:$DG$29,$B$23,0) -> 5 | N11: =IFERROR(M11/L11,0) -> 1 | O11: =L11-M11 -> 0 | P11: =VLOOKUP(A11,'Giao CT'!$D$6:$S$20,6,0) -> 4 | Q11: =VLOOKUP(A11,GBOC!$E$7:$DG$29,$B$24,0) -> 4 | R11: =IFERROR(Q11/P11,0) -> 1 | S11: =P11-Q11 -> 0 | T11: =VLOOKUP(A11,'Giao CT'!$D$6:$S$20,7,0) -> 3 | U11: =VLOOKUP(A11,GBOC!$E$7:$DG$29,$B$25,0) -> 5 | V11: =IFERROR(U11/T11,0) -> 1.6666667 | W11: =T11-U11 -> -2 | X11: =VLOOKUP(A11,'Giao CT'!$D$6:$S$20,8,0) -> 1 | Y11: =VLOOKUP(A11,GBOC!$E$7:$DG$29,$B$26,0) -> 3 | Z11: =IFERROR(Y11/X11,0) -> 3 | AA11: =X11-Y11 -> -2 | AB11: =VLOOKUP(A11,'Giao CT'!$D$6:$S$20,9,0) -> 30 | AC11: =VLOOKUP(A11,GBOC!$E$7:$DG$29,$B$27,0) -> 30 | AD11: =IFERROR(AC11/AB11,0) -> 1 | AE11: =AB11-AC11 -> 0 | AF11: =VLOOKUP(A11,'Giao CT'!$D$6:$S$20,10,0) -> 8 | AG11: =VLOOKUP(A11,GBOC!$E$7:$DG$29,$B$28,0) -> 12 | AH11: =IFERROR(AG11/AF11,0) -> 1.5 | AI11: =AF11-AG11 -> -4 | AJ11: =VLOOKUP(A11,'Giao CT'!$D$6:$S$20,11,0) -> 4 | AK11: =VLOOKUP(B11,'TH NV'!$B$5:$BG$18,36,0) -> 0 | AL11: =200%-IFERROR(AK11/AJ11,0) -> 2 | AM11: =MAX(AL11,0) -> 2 | AN11: =VLOOKUP(A11,'Giao CT'!$D$6:$S$20,12,0) -> 5 | AO11: =VLOOKUP(A11,GBOC!$E$7:$DG$29,$B$30,0) -> 3 | AP11: =200%-IFERROR(AO11/AN11,0) -> 1.4 | AQ11: =MAX(AP11,0) -> 1.4 | AR11: 0.97 | AS11: =(VLOOKUP(B11,cuoc!$B$7:$P$27,14,0))*1% -> 0.9673 | AT11: =IF(AS11<94.5%,0,IF(AS11<95.54%,50%,IF(AS11<AR11,80%,100%+(30%*(AS11-AR11)/3.39%)))) -> 0.8 | AU11: =AR11-AS11 -> 0.0027 | AV11: =VLOOKUP(A11,'Giao CT'!$D$6:$S$20,14,0) -> 3 | AW11: =VLOOKUP(A11,GBOC!$E$7:$DG$29,$B$32,0) -> 1 | AX11: =AW11/AV11 -> 0.33333333 | AY11: =AV11-AW11 -> 2 | AZ11: =VLOOKUP(A11,'Giao CT'!$D$6:$S$20,15,0) -> 1 | BA11: =VLOOKUP(A11,GBOC!$E$7:$DG$29,$B$33,0) -> 1 | BB11: =IFERROR(BA11/AZ11,1) -> 1 | BC11: =AZ11-BA11 -> 0 | BD11: =VLOOKUP(A11,'Giao CT'!$D$6:$S$20,16,0) -> 0 | BE11: =VLOOKUP(A11,GBOC!$E$7:$DG$29,$B$34,0) -> 0 | BF11: =IFERROR(BE11/BD11,1) -> 1 | BG11: =BD11-BE11 -> 0
A12: CNKD_LDG_HUNGTV1 | B12: HUNGTV1_LDG_CNKD | C12: SONTV10_NVKDDB_LDG | D12: =VLOOKUP(A12,'Giao CT'!$D$6:$S$20,3,0) -> 7 | E12: =VLOOKUP(A12,GBOC!$E$7:$DG$29,$B$21,0) -> 5 | F12: =IFERROR(E12/D12,0) -> 0.71428571 | G12: =D12-E12 -> 2 | H12: =VLOOKUP(A12,'Giao CT'!$D$6:$S$20,4,0) -> 3 | I12: =VLOOKUP(A12,GBOC!$E$7:$DG$29,$B$22,0) -> 4 | J12: =IFERROR(I12/H12,0) -> 1.3333333 | K12: =H12-I12 -> -1 | L12: =VLOOKUP(A12,'Giao CT'!$D$6:$S$20,5,0) -> 4 | M12: =VLOOKUP(A12,GBOC!$E$7:$DG$29,$B$23,0) -> 2 | N12: =IFERROR(M12/L12,0) -> 0.5 | O12: =L12-M12 -> 2 | P12: =VLOOKUP(A12,'Giao CT'!$D$6:$S$20,6,0) -> 4 | Q12: =VLOOKUP(A12,GBOC!$E$7:$DG$29,$B$24,0) -> 3 | R12: =IFERROR(Q12/P12,0) -> 0.75 | S12: =P12-Q12 -> 1 | T12: =VLOOKUP(A12,'Giao CT'!$D$6:$S$20,7,0) -> 3 | U12: =VLOOKUP(A12,GBOC!$E$7:$DG$29,$B$25,0) -> 0 | V12: =IFERROR(U12/T12,0) -> 0 | W12: =T12-U12 -> 3 | X12: =VLOOKUP(A12,'Giao CT'!$D$6:$S$20,8,0) -> 1 | Y12: =VLOOKUP(A12,GBOC!$E$7:$DG$29,$B$26,0) -> 0 | Z12: =IFERROR(Y12/X12,0) -> 0 | AA12: =X12-Y12 -> 1 | AB12: =VLOOKUP(A12,'Giao CT'!$D$6:$S$20,9,0) -> 30 | AC12: =VLOOKUP(A12,GBOC!$E$7:$DG$29,$B$27,0) -> 9 | AD12: =IFERROR(AC12/AB12,0) -> 0.3 | AE12: =AB12-AC12 -> 21 | AF12: =VLOOKUP(A12,'Giao CT'!$D$6:$S$20,10,0) -> 8 | AG12: =VLOOKUP(A12,GBOC!$E$7:$DG$29,$B$28,0) -> 0 | AH12: =IFERROR(AG12/AF12,0) -> 0 | AI12: =AF12-AG12 -> 8 | AJ12: =VLOOKUP(A12,'Giao CT'!$D$6:$S$20,11,0) -> 4 | AK12: =VLOOKUP(B12,'TH NV'!$B$5:$BG$18,36,0) -> 5 | AL12: =200%-IFERROR(AK12/AJ12,0) -> 0.75 | AM12: =MAX(AL12,0) -> 0.75 | AN12: =VLOOKUP(A12,'Giao CT'!$D$6:$S$20,12,0) -> 3 | AO12: =VLOOKUP(A12,GBOC!$E$7:$DG$29,$B$30,0) -> 1 | AP12: =200%-IFERROR(AO12/AN12,0) -> 1.6666667 | AQ12: =MAX(AP12,0) -> 1.6666667 | AR12: 0.97 | AS12: =(VLOOKUP(B12,cuoc!$B$7:$P$27,14,0))*1% -> 0.9298 | AT12: =IF(AS12<94.5%,0,IF(AS12<95.54%,50%,IF(AS12<AR12,80%,100%+(30%*(AS12-AR12)/3.39%)))) -> 0 | AU12: =AR12-AS12 -> 0.0402 | AV12: =VLOOKUP(A12,'Giao CT'!$D$6:$S$20,14,0) -> 1 | AW12: =VLOOKUP(A12,GBOC!$E$7:$DG$29,$B$32,0) -> 0 | AX12: =AW12/AV12 -> 0 | AY12: =AV12-AW12 -> 1 | AZ12: =VLOOKUP(A12,'Giao CT'!$D$6:$S$20,15,0) -> 1 | BA12: =VLOOKUP(A12,GBOC!$E$7:$DG$29,$B$33,0) -> 0 | BB12: =IFERROR(BA12/AZ12,1) -> 0 | BC12: =AZ12-BA12 -> 1 | BD12: =VLOOKUP(A12,'Giao CT'!$D$6:$S$20,16,0) -> 0 | BE12: =VLOOKUP(A12,GBOC!$E$7:$DG$29,$B$34,0) -> 0 | BF12: =IFERROR(BE12/BD12,1) -> 1 | BG12: =BD12-BE12 -> 0
A13: CNKD_LDG_HUONGVTT | B13: HUONGVTT_LDG_CNKD | C13: SONTV10_NVKDDB_LDG | D13: =VLOOKUP(A13,'Giao CT'!$D$6:$S$20,3,0) -> 7 | E13: =VLOOKUP(A13,GBOC!$E$7:$DG$29,$B$21,0) -> 7 | F13: =IFERROR(E13/D13,0) -> 1 | G13: =D13-E13 -> 0 | H13: =VLOOKUP(A13,'Giao CT'!$D$6:$S$20,4,0) -> 3 | I13: =VLOOKUP(A13,GBOC!$E$7:$DG$29,$B$22,0) -> 3 | J13: =IFERROR(I13/H13,0) -> 1 | K13: =H13-I13 -> 0 | L13: =VLOOKUP(A13,'Giao CT'!$D$6:$S$20,5,0) -> 4 | M13: =VLOOKUP(A13,GBOC!$E$7:$DG$29,$B$23,0) -> 4 | N13: =IFERROR(M13/L13,0) -> 1 | O13: =L13-M13 -> 0 | P13: =VLOOKUP(A13,'Giao CT'!$D$6:$S$20,6,0) -> 4 | Q13: =VLOOKUP(A13,GBOC!$E$7:$DG$29,$B$24,0) -> 2 | R13: =IFERROR(Q13/P13,0) -> 0.5 | S13: =P13-Q13 -> 2 | T13: =VLOOKUP(A13,'Giao CT'!$D$6:$S$20,7,0) -> 3 | U13: =VLOOKUP(A13,GBOC!$E$7:$DG$29,$B$25,0) -> 4 | V13: =IFERROR(U13/T13,0) -> 1.3333333 | W13: =T13-U13 -> -1 | X13: =VLOOKUP(A13,'Giao CT'!$D$6:$S$20,8,0) -> 1 | Y13: =VLOOKUP(A13,GBOC!$E$7:$DG$29,$B$26,0) -> 3 | Z13: =IFERROR(Y13/X13,0) -> 3 | AA13: =X13-Y13 -> -2 | AB13: =VLOOKUP(A13,'Giao CT'!$D$6:$S$20,9,0) -> 30 | AC13: =VLOOKUP(A13,GBOC!$E$7:$DG$29,$B$27,0) -> 26 | AD13: =IFERROR(AC13/AB13,0) -> 0.86666667 | AE13: =AB13-AC13 -> 4 | AF13: =VLOOKUP(A13,'Giao CT'!$D$6:$S$20,10,0) -> 8 | AG13: =VLOOKUP(A13,GBOC!$E$7:$DG$29,$B$28,0) -> 3 | AH13: =IFERROR(AG13/AF13,0) -> 0.375 | AI13: =AF13-AG13 -> 5 | AJ13: =VLOOKUP(A13,'Giao CT'!$D$6:$S$20,11,0) -> 4 | AK13: =VLOOKUP(B13,'TH NV'!$B$5:$BG$18,36,0) -> 3 | AL13: =200%-IFERROR(AK13/AJ13,0) -> 1.25 | AM13: =MAX(AL13,0) -> 1.25 | AN13: =VLOOKUP(A13,'Giao CT'!$D$6:$S$20,12,0) -> 4 | AO13: =VLOOKUP(A13,GBOC!$E$7:$DG$29,$B$30,0) -> 1 | AP13: =200%-IFERROR(AO13/AN13,0) -> 1.75 | AQ13: =MAX(AP13,0) -> 1.75 | AR13: 0.97 | AS13: =(VLOOKUP(B13,cuoc!$B$7:$P$27,14,0))*1% -> 0.9724 | AT13: =IF(AS13<94.5%,0,IF(AS13<95.54%,50%,IF(AS13<AR13,80%,100%+(30%*(AS13-AR13)/3.39%)))) -> 1.0212389 | AU13: =AR13-AS13 -> -0.0024 | AV13: =VLOOKUP(A13,'Giao CT'!$D$6:$S$20,14,0) -> 1 | AW13: =VLOOKUP(A13,GBOC!$E$7:$DG$29,$B$32,0) -> 0 | AX13: =AW13/AV13 -> 0 | AY13: =AV13-AW13 -> 1 | AZ13: =VLOOKUP(A13,'Giao CT'!$D$6:$S$20,15,0) -> 1 | BA13: =VLOOKUP(A13,GBOC!$E$7:$DG$29,$B$33,0) -> 0 | BB13: =IFERROR(BA13/AZ13,1) -> 0 | BC13: =AZ13-BA13 -> 1 | BD13: =VLOOKUP(A13,'Giao CT'!$D$6:$S$20,16,0) -> 0 | BE13: =VLOOKUP(A13,GBOC!$E$7:$DG$29,$B$34,0) -> 0 | BF13: =IFERROR(BE13/BD13,1) -> 1 | BG13: =BD13-BE13 -> 0
